Workbook

Sheet Resumen sin TD
A1: - | L1: 100 | M1: 50 | N1: 10
G2: Valores | L2: Costos B2B Según volumen | P2: Margenes B2B Según volumen
A3: Marca | B3: Categoria Padre | C3: Categoria Hijo | D3: Descripcion | E3: Sku | F3: Status MLL | G3: Precio Etiqueta | H3: Costo Oferta | I3: Costo MLL | L3: 0 | M3: 0.07 | N3: 0.14 | P3: 30+ | Q3: 21 y 29 | R3: 10 y 20
A4: Bandú | B4: Accesorios de Bebe | C4: Accesorios de Bebe | D4: Mecedor Electrico Coche Recargable Bebe Baby Chick Bandú | E4: BDBBYCHK | F4: Mix MLL | G4: 54990 | H4: 35288 | I4: 20716 | L4: 20716 | M4: 22196 | N4: 23675 | P4: 0.3 | Q4: 0.25 | R4: 0.2
A5: Bandú | B5: Jueguetes de Rol | C5: Cocina y Accesorios | D5: Casa De Muñecas Clásica Madera Rosada Con Accesorios Bandú | E5: BDCASMUÑEC | F5: Mix MLL | G5: 99990 | H5: 35288 | I5: 23592 | L5: 23592 | M5: 25277 | N5: 26962 | P5: 0.2 | Q5: 0.15 | R5: 0.09
A6: Bandú | B6: Jueguetes de Rol | C6: Cocina y Accesorios | D6: Cocina de Juguete Infantil Niños Madera 11 Accesorios Bandú | E6: BDCOCMEDI | F6: Mix MLL | G6: 119990 | H6: 58818 | I6: 32822 | L6: 32822 | M6: 35166 | N6: 37511 | P6: 0.34 | Q6: 0.29 | R6: 0.24
A7: Bandú | B7: Jueguetes de Rol | C7: Cocina y Accesorios | D7: Cocina de Juguete Infantil Niños Madera Accesorios Bandú | E7: BDCOCGRND | F7: Mix MLL | G7: 139990 | H7: 70582 | I7: 36284 | L7: 36284 | M7: 38876 | N7: 41468 | P7: 0.39 | Q7: 0.34 | R7: 0.3
A8: Bandú | B8: Jueguetes de Rol | C8: Cocina y Accesorios | D8: Cocina de Juguete Infantil Niños Madera Rosada con Acc Bandú | E8: BDCOCPQMD | F8: Mix MLL | G8: 99990 | H8: 47053 | I8: 27042 | L8: 27042 | M8: 28973 | N8: 30905 | P8: 0.32 | Q8: 0.27 | R8: 0.22 | T8: 1656603353038
A9: Bandú | B9: Jueguetes de Rol | C9: Cocina y Accesorios | D9: Juguete Infantil mini Electrodomésticos Cocina Madera Bandú | E9: BDELECTCOC | F9: Mix MLL | G9: 24990 | H9: 11759 | I9: 6246 | L9: 6246 | M9: 6692 | N9: 7138 | P9: 0.37 | Q9: 0.32 | R9: 0.28
A10: Bandú | B10: Jueguetes de Rol | C10: Cocina y Accesorios | D10: Set Juego Mini Cocina de Juguete Alimentos Madera Bandú | E10: BDCOCMIN | F10: Mix MLL | G10: 29990 | H10: 11759 | I10: 7906 | L10: 7906 | M10: 8471 | N10: 9035 | P10: 0.2 | Q10: 0.14 | R10: 0.09
A11: Bandú | B11: Jueguetes de Rol | C11: Cocina y Accesorios | D11: Set Juego Pastelería Corta Postre Infantil Niño Madera Bandú | E11: BDSETPAST | F11: Mix MLL | G11: 24990 | H11: 11759 | I11: 6889 | L11: 6889 | M11: 7381 | N11: 7873 | P11: 0.3 | Q11: 0.25 | R11: 0.2
A12: Bandú | B12: Jueguetes de Rol | C12: Cocina y Accesorios | D12: Set Juego Tazas De Té Juguete Didáctico 16pcs Madera Bandú | E12: BDJUESETTE | F12: Mix MLL | G12: 29990 | H12: 11759 | I12: 6930 | L12: 6930 | M12: 7425 | N12: 7920 | P12: 0.3 | Q12: 0.25 | R12: 0.2
A13: Bandú | B13: Jueguetes de Rol | C13: Juegos de Oficio | D13: Set Juego de Roles Doctor Niños Madera 12 pcs Bandú | E13: BDSETDOC | F13: Mix MLL | G13: 24990 | H13: 8818 | I13: 5410 | L13: 5410 | M13: 5796 | N13: 6183 | P13: 0.27 | Q13: 0.22 | R13: 0.17
A14: Bandú | B14: Jueguetes de Rol | C14: Maquillaje y Belleza | D14: Juego de Maquillaje Set Belleza de Roll Niños Madera Bandú | E14: BDSETMAQ | F14: Mix MLL | G14: 24990 | H14: 11759 | I14: 6056 | L14: 6056 | M14: 6489 | N14: 6921 | P14: 0.39 | Q14: 0.34 | R14: 0.3
A15: Bandú | B15: Jueguetes de Rol | C15: Maquillaje y Belleza | D15: Tocador Infantil Para Niñas Espejo Maquillaje Madera Bandú | E15: BDTOCMD-WH | F15: Mix MLL | G15: 119990 | H15: 58818 | I15: 33401 | L15: 33401 | M15: 35787 | N15: 38173 | P15: 0.32 | Q15: 0.28 | R15: 0.23
A16: Bandú | B16: Juguetes de Armado | C16: Pistas y Vehiculos | D16: Pista de Autos y Tren de Madera Juego Didactico 70pcs Bandú | E16: BDJUETRE | F16: Mix MLL | G16: 64990 | H16: 29406 | I16: 16420 | L16: 16420 | M16: 17593 | N16: 18766 | P16: 0.34 | Q16: 0.29 | R16: 0.24
A17: Bandú | B17: Juguetes de Armado | C17: Pistas y Vehiculos | D17: Set Autos de Juguete Tren Pista y Señaleticas Madera Bandú | E17: BDJUEAUT | F17: Mix MLL | G17: 29990 | H17: 11759 | I17: 7928 | L17: 7928 | M17: 8494 | N17: 9061 | P17: 0.2 | Q17: 0.14 | R17: 0.08
A18: Bandú | B18: Juguetes de Armado | C18: Sets de Construccion | D18: Juego de Construcción Herramientas Madera para Niños Bandú | E18: BDMESHERRA | F18: Mix MLL | G18: 64990 | H18: 29406 | I18: 20332 | L18: 20332 | M18: 21784 | N18: 23237 | P18: 0.18 | Q18: 0.12 | R18: 0.06
A19: Bandú | B19: Juguetes de Motricidad | C19: Andador y Correpasillos | D19: Andador Correpasillos Bebe Didáctico Madera Bandú Rosado | E19: BDANDDIDAC-PK | F19: Mix MLL | G19: 54990 | H19: 29406 | I19: 15240 | L19: 15240 | M19: 16329 | N19: 17417 | P19: 0.38 | Q19: 0.34 | R19: 0.3
A20: Bandú | B20: Juguetes de Motricidad | C20: Andador y Correpasillos | D20: Andador Correpasillos Bebe Didáctico Madera Bandú Verde | E20: BDANDDIDAC-GR | F20: Mix MLL | G20: 54990 | H20: 29406 | I20: 15911 | L20: 15911 | M20: 17047 | N20: 18184 | P20: 0.36 | Q20: 0.31 | R20: 0.26
... A30: Bandú | B30: (en blanco) | C30: (en blanco) | D30: Gimancio Infantil Juego Pikler Parque 8 en 1 Bandu | E30: BDGIMPIK | F30: Mix MLL | G30: 349990 | H30: 170582 | I30: 86480 | L30: 86480 | M30: 92657 | N30: 98835 | P30: 0.4 | Q30: 0.35 | R30: 0.31
A31: Total Bandú | G31: 1938730 | H31: 923371 | I31: 511878
A32: Dynamo Tools | B32: Herramientas Eléctricas | C32: Otras | D32: Hidrolavadora eléctrica Dynamo WP 1800w 130bar 220/240V 60Hz | E32: DYNHYDLA | F32: Mix MLL | G32: 99990 | H32: 47053 | I32: 32555 | L32: 32555 | M32: 34880 | N32: 37206 | P32: 0.18 | Q32: 0.12 | R32: 0.06
A33: Dynamo Tools | B33: Herramientas Eléctricas | C33: Taladro y Atornilladores | D33: Kit Taladro Destornillador Inalámbrico Dynamo 21v 2 Baterías | E33: DYNTALSPER | F33: Mix MLL | G33: 59990 | H33: 17641 | I33: 10941 | L33: 10941 | M33: 11722 | N33: 12504 | P33: 0.26 | Q33: 0.21 | R33: 0.16
A34: Dynamo Tools | B34: Herramientas Eléctricas | C34: Taladro y Atornilladores | D34: Llave de Impacto Inalámbrica Dynamo 21V + 2 Baterias y Acss | E34: DYNLLAIMP | F34: Mix MLL | G34: 99990 | H34: 35288 | I34: 25907 | L34: 25907 | M34: 27757 | N34: 29608 | P34: 0.13 | Q34: 0.06 | R34: 0
A35: Dynamo Tools | B35: Herramientas Eléctricas | C35: Taladro y Atornilladores | D35: Pack Taladro Percutor + Atornillador de Impacto 21V Dynamo | E35: DYNTALIMPA | F35: Mix MLL | G35: 149990 | H35: 52935 | I35: 39607 | L35: 39607 | M35: 42436 | N35: 45265 | P35: 0.11 | Q35: 0.05 | R35: -0.02
A36: Dynamo Tools | B36: Herramientas Eléctricas | C36: Taladro y Atornilladores | D36: Taladro Desatornillador Inalámbrico Dynamo YM 21V 2 baterías | E36: DYNTALSCA | F36: Mix MLL | G36: 39990 | H36: 11759 | I36: 8630 | L36: 8630 | M36: 9246 | N36: 9863 | P36: 0.13 | Q36: 0.06 | R36: 0
A37: Dynamo Tools | B37: Herramientas Eléctricas | C37: Taladro y Atornilladores | D37: Taladro Inalámbrico Dynamo Rotomartillo Percutor 2 Baterías | E37: DYNTALPOW | F37: Mix MLL | G37: 89990 | H37: 35288 | I37: 25079 | L37: 25079 | M37: 26870 | N37: 28662 | P37: 0.15 | Q37: 0.09 | R37: 0.03
A38: Dynamo Tools | B38: Herramientas Eléctricas | C38: Taladro y Atornilladores | D38: Taladro Percutor Inalámbrico Dynamo 21v 2 Baterías + Accs | E38: DYNTALCPER | F38: Mix MLL | G38: 69990 | H38: 17641 | I38: 11893 | L38: 11893 | M38: 12742 | N38: 13592 | P38: 0.2 | Q38: 0.14 | R38: 0.08
A39: Total Dynamo Tools | G39: 609930 | H39: 217606 | I39: 154612
A40: Innovate-K | B40: Gasfiteria | C40: Baroscopios | D40: Cámara de inspección alcantarillado con pantalla LCD de 7 pulgadas H6 endoscopio boroscopio | E40: 1661880000000 | F40: Mix MLL | G40: 699990 | H40: 382347 | I40: 275044 | L40: 275044 | M40: 294689 | N40: 314337 | P40: 0.14 | Q40: 0.08 | R40: 0.02
A41: Innovate-K | B41: Gasfiteria | C41: Baroscopios | D41: Cámara de Inspección Baroscopio 512 Hz con Sonda 20 Mts H5 | E41: INNCAMINSH5512-20 | F41: Mix MLL | G41: 1699990 | H41: 823524 | I41: 423998 | L41: 423998 | M41: 454282 | N41: 484570 | P41: 0.39 | Q41: 0.34 | R41: 0.3
A42: Innovate-K | B42: Gasfiteria | C42: Baroscopios | D42: Cámara de Inspección Baroscopio con Sonda 20 Mts H5 | E42: INNCAMINSH5-20 | F42: Mix MLL | G42: 1149990 | H42: 558818 | I42: 282666 | L42: 282666 | M42: 302855 | N42: 323048 | P42: 0.4 | Q42: 0.36 | R42: 0.31
A43: Innovate-K | B43: Gasfiteria | C43: Baroscopios | D43: Cámara de Inspección Baroscopio con Sonda 40 Mts H6 | E43: INNCAMINSH6-40 | F43: Mix MLL | G43: 1999990 | H43: 588229 | I43: 302856 | L43: 302856 | M43: 324487 | N43: 346122 | P43: 0.39 | Q43: 0.34 | R43: 0.3
A44: Innovate-K | B44: Gasfiteria | C44: Baroscopios | D44: Cámara de Inspección Baroscopio con Sonda 40 Mts TP9200 | E44: INCAMINS92-40 | F44: Mix MLL | G44: 899990 | H44: 470582 | I44: 293682 | L44: 293682 | M44: 314658 | N44: 335637 | P44: 0.26 | Q44: 0.2 | R44: 0.15
A45: Innovate-K | B45: Gasfiteria | C45: Baroscopios | D45: Cámara de Inspección de Tuberías Endoscopio Industrial TP9600 | E45: INNCAMINS-96 | F45: Mix MLL | G45: 1499990 | H45: 764700 | I45: 432031 | L45: 432031 | M45: 462889 | N45: 493751 | P45: 0.33 | Q45: 0.28 | R45: 0.23
A46: Innovate-K | B46: Gasfiteria | C46: Baroscopios | D46: Cámara de Inspección de Tuberías Endoscopio Industrial TP9607F | E46: INNCAMINS-7F | F46: Mix MLL | G46: 1699990 | H46: 941171 | I46: 553437 | L46: 553437 | M46: 592966 | N46: 632501 | P46: 0.3 | Q46: 0.25 | R46: 0.2
A47: Innovate-K | B47: Gasfiteria | C47: Baroscopios | D47: Cámara de Inspección de Tuberías Endoscopio Industrial U9 | E47: INNCAMINS-U9 | F47: Mix MLL | G47: 159990 | H47: 88229 | I47: 50149 | L47: 50149 | M47: 53731 | N47: 57313 | P47: 0.32 | Q47: 0.28 | R47: 0.23
A48: Innovate-K | B48: Gasfiteria | C48: Baroscopios | D48: Cámara de Inspección Baroscopio con Sonda 70 Mts H3 | E48: INNCAMINSH3-70 | F48: Mix MLL | G48: 7199990 | H48: 3529406 | I48: 29251 | L48: 29251 | M48: 31340 | N48: 33430 | P48: 0.99 | Q48: 0.99 | R48: 0.99
A49: Innovate-K | B49: Gasfiteria | C49: Baroscopios | D49: Cámara de Inspección Baroscopio con Sonda 20 Mts TP9200 | E49: 1661880000000 | F49: Mix MLL | G49: 599990 | H49: 323524 | I49: 237256 | L49: 237256 | M49: 254202 | N49: 271150 | P49: 0.13 | Q49: 0.06 | R49: 0
...

Sheet Maestra
E2: INFORMACION CLIENTE | G2: INFORMACION UNIONX | J2: INFORMACION CLIENTE | R2: 0.3
E3: UnionX | F3: Cliente | G3: UnionX | J3: Precios Ciente | L3: Costo Cliente | N3: Margen | P3: Status
A4: Marca | B4: Sku | C4: Seccion | D4: Familia | E4: Grupo | F4: Descripcion | G4: Costo MLL | H4: ROI | I4: Utilidad UnionX | J4: P Etiqueta | K4: PVP Oferta | L4: Costo | M4: Costo Oferta | N4: Margen Master | O4: Margen Oferta | P4: Status MLL | Q4: MG FRONT | R4: MG COMISION
A5: Bandú | B5: BDBBYCHK | C5: Accesorios de Bebe | D5: Accesorios de Bebe | E5: Baby Chick Bandú - Mecedor eléctrico de bebé | F5: Mecedor Eléctrico Coche Recargable Bebé Baby Chick Bandú | G5: 20716 | H5: 0.41 | I5: 14572 | J5: $64.990 | K5: $59.990 | L5: 38229 | M5: 35288 | N5: 0.3 | O5: 0.3 | P5: Mix UnionX | Q5: 0.59 | R5: 0.36
A6: Bandú | B6: BDCASMUÑEC | C6: Jueguetes de Rol | D6: Cocina y Accesorios | E6: Casa De Muñecas Clásica Madera Rosada Con Accesorios Bandú | F6: Casa De Muñecas Clásica Madera Rosada Con Accesorios Bandú | G6: 23592 | H6: 0.33 | I6: 11696 | J6: $99.990 | K6: $59.990 | L6: 58818 | M6: 35288 | N6: 0.3 | O6: 0.3 | P6: Mix UnionX | Q6: 0.53 | R6: 0.3
A7: Bandú | B7: BDCOCMEDI | C7: Jueguetes de Rol | D7: Cocina y Accesorios | E7: Cocina de Juguete Infantil Niños Madera 11 Accesorios Bandú | F7: Cocina de Juguete Infantil Niños Madera 11 Accesorios Bandú | G7: 28393 | H7: 0.52 | I7: 30424 | J7: $119.990 | K7: $99.990 | L7: 70582 | M7: 58818 | N7: 0.3 | O7: 0.3 | P7: Mix UnionX | Q7: 0.66 | R7: 0.43
A8: Bandú | B8: BDCOCGRND | C8: Jueguetes de Rol | D8: Cocina y Accesorios | E8: Cocina de Juguete Infantil Niños Madera Accesorios Bandú | F8: Cocina de Juguete Infantil Niños Madera Accesorios Bandú | G8: 31896 | H8: 0.55 | I8: 38687 | J8: $139.990 | K8: $119.990 | L8: 82347 | M8: 70582 | N8: 0.3 | O8: 0.3 | P8: Mix UnionX | Q8: 0.68 | R8: 0.45
A9: Bandú | B9: BDCOCPQMD | C9: Jueguetes de Rol | D9: Cocina y Accesorios | E9: Cocina de Juguete Infantil Niños Madera Rosada con Acc Bandú | F9: Cocina de Juguete Infantil Niños Madera Rosada con Acc Bandú | G9: 26348 | H9: 0.36 | I9: 14822 | J9: $99.990 | K9: $69.990 | L9: 58818 | M9: 41171 | N9: 0.3 | O9: 0.3 | P9: Mix UnionX | Q9: 0.55 | R9: 0.32
A10: Bandú | B10: BDELECTCOC | C10: Jueguetes de Rol | D10: Cocina y Accesorios | E10: Juguete Infantil mini Electrodomésticos Cocina Madera Bandú | F10: Juguete Infantil Mini Electrodomésticos Cocina Madera Bandú | G10: 5823 | H10: 0.42 | I10: 4171 | J10: $24.990 | K10: $16.990 | L10: 14700 | M10: 9994 | N10: 0.3 | O10: 0.3 | P10: Mix UnionX | Q10: 0.59 | R10: 0.36
A11: Bandú | B11: BDCOCMIN | C11: Jueguetes de Rol | D11: Cocina y Accesorios | E11: Set Juego Mini Cocina de Juguete Alimentos Madera Bandú | F11: Set Juego Mini Cocina de Juguete Alimentos Madera Bandú | G11: 7906 | H11: 0.33 | I11: 3853 | J11: $29.990 | K11: $19.990 | L11: 17641 | M11: 11759 | N11: 0.3 | O11: 0.3 | P11: Mix UnionX | Q11: 0.53 | R11: 0.3
A12: Bandú | B12: BDSETPAST | C12: Jueguetes de Rol | D12: Cocina y Accesorios | E12: Set Juego Pastelería Corta Postre Infantil Niño Madera Bandú | F12: Set Juego Pastelería Corta Postre Infantil Niño Madera Bandú | G12: 6889 | H12: 0.31 | I12: 3105 | J12: $24.990 | K12: $16.990 | L12: 14700 | M12: 9994 | N12: 0.3 | O12: 0.3 | P12: Mix UnionX | Q12: 0.52 | R12: 0.29
A13: Bandú | B13: BDJUESETTE | C13: Jueguetes de Rol | D13: Cocina y Accesorios | E13: Set Juego Tazas De Té Juguete Didáctico 16pcs Madera Bandú | F13: Set Juego Tazas De Té Juguete Didáctico 16pcs Madera Bandú | G13: 6930 | H13: 0.41 | I13: 4829 | J13: $29.990 | K13: $19.990 | L13: 17641 | M13: 11759 | N13: 0.3 | O13: 0.3 | P13: Mix UnionX | Q13: 0.59 | R13: 0.36
A14: Bandú | B14: BDSETDOC | C14: Jueguetes de Rol | D14: Juegos de Oficio | E14: Set Juego de Roles Doctor Niños Madera 12 pcs Bandú | F14: Set Juego de Roles Doctor Niños Madera 12 pcs Bandú | G14: 4770 | H14: 0.46 | I14: 4048 | J14: $24.990 | K14: $14.990 | L14: 14700 | M14: 8818 | N14: 0.3 | O14: 0.3 | P14: Mix UnionX | Q14: 0.62 | R14: 0.39
A15: Bandú | B15: BDSETMAQ | C15: Jueguetes de Rol | D15: Maquillaje y Belleza | E15: Juego de Maquillaje Set Belleza de Roll Niños Madera Bandú | F15: Juego de Maquillaje Set Belleza de Roll Niños Madera Bandú | G15: 4770 | H15: 0.59 | I15: 6989 | J15: $24.990 | K15: $19.990 | L15: 14700 | M15: 11759 | N15: 0.3 | O15: 0.3 | P15: Mix UnionX | Q15: 0.72 | R15: 0.49
A16: Bandú | B16: BDTOCMD-WH | C16: Jueguetes de Rol | D16: Maquillaje y Belleza | E16: Tocador Infantil Para Niñas Espejo Maquillaje Madera Bandú | F16: Tocador Infantil Para Niñas Espejo Maquillaje Madera Bandú | G16: 33401 | H16: 0.43 | I16: 25417 | J16: $119.990 | K16: $99.990 | L16: 70582 | M16: 58818 | N16: 0.3 | O16: 0.3 | P16: Mix UnionX | Q16: 0.6 | R16: 0.37
... A46: GOYA | B46: GOYAHOSP-CV | C46: Aromatización | D46: Home Spray | E46: Home Spray 500ml Aroma Citron Verveine GOYA | F46: Home Spray 500ml Aroma Citron Verveine GOYA | G46: 7500 | H46: 0.25 | I46: 2494 | J46: $17.990 | K46: $16.990 | L46: 10582 | M46: 9994 | N46: 0.3 | O46: 0.3 | P46: Mix UnionX | Q46: 0.47 | R46: 0.24
A47: Innovate-K | B47: 1661877072053 | C47: Gasfiteria | D47: Baroscopios | E47: Cámara de inspección alcantarillado con pantalla LCD de 7 pulgadas H6 endoscopio boroscopio | F47: Cámara de inspección alcantarillado con pantalla LCD de 7 pulgadas H6 endoscopio boroscopio | G47: 275044 | H47: 0.28 | I47: 107303 | J47: $699.990 | K47: $649.990 | L47: 411759 | M47: 382347 | N47: 0.3 | O47: 0.3 | P47: Mix UnionX | Q47: 0.5 | R47: 0.27
A48: Innovate-K | B48: INNCAMINSH5512-20 | C48: Gasfiteria | D48: Baroscopios | E48: Cámara de Inspección Baroscopio 512 Hz con Sonda 20 Mts H5 | F48: Cámara de Inspección Baroscopio 512 Hz con Sonda 20 Mts H5 | G48: 423998 | H48: 0.49 | I48: 399526 | J48: $1.699.990 | K48: $1.399.990 | L48: 999994 | M48: 823524 | N48: 0.3 | O48: 0.3 | P48: Mix UnionX | Q48: 0.64 | R48: 0.41
A49: Innovate-K | B49: INNCAMINSH3-70 | C49: Gasfiteria | D49: Baroscopios | E49: Cámara de Inspección Baroscopio con Sonda 20 Mts H3 | F49: Cámara de Inspección Baroscopio con Sonda 70 Mts H3 | G49: 1867612 | H49: 0.47 | I49: 1661794 | J49: $7.199.990 | K49: $5.999.990 | L49: 4235288 | M49: 3529406 | N49: 0.3 | O49: 0.3 | P49: Mix UnionX | Q49: 0.63 | R49: 0.4
A50: Innovate-K | B50: INNCAMINSH5-20 | C50: Gasfiteria | D50: Baroscopios | E50: Cámara de Inspección Baroscopio con Sonda 20 Mts H5 | F50: Cámara de Inspección Baroscopio con Sonda 20 Mts H5 | G50: 282666 | H50: 0.49 | I50: 276152 | J50: $1.149.990 | K50: $949.990 | L50: 676465 | M50: 558818 | N50: 0.3 | O50: 0.3 | P50: Mix UnionX | Q50: 0.65 | R50: 0.42
A51: Innovate-K | B51: INNCAMINSH6-40 | C51: Gasfiteria | D51: Baroscopios | E51: Cámara de Inspección Baroscopio con Sonda 40 Mts H6 | F51: Cámara de Inspección Baroscopio con Sonda 40 Mts H6 | G51: 302856 | H51: 0.49 | I51: 285373 | J51: $1.999.990 | K51: $999.990 | L51: 1176465 | M51: 588229 | N51: 0.3 | O51: 0.3 | P51: Mix UnionX | Q51: 0.64 | R51: 0.41
A52: Innovate-K | B52: INCAMINS92-40 | C52: Gasfiteria | D52: Baroscopios | E52: Cámara de Inspección Baroscopio con Sonda 40 Mts TP9200 | F52: Cámara de Inspección Baroscopio con Sonda 40 Mts TP9200 | G52: 293682 | H52: 0.38 | I52: 176900 | J52: $899.990 | K52: $799.990 | L52: 529406 | M52: 470582 | N52: 0.3 | O52: 0.3 | P52: Mix UnionX | Q52: 0.56 | R52: 0.33
A53: Innovate-K | B53: 1661877043628 | C53: Gasfiteria | D53: Baroscopios | E53: Cámara de inspección de tuberías de alcantarillado TP9200 endoscopio boroscopio | F53: Cámara de Inspección Baroscopio con Sonda 20 Mts TP9200 | G53: 237256 | H53: 0.27 | I53: 86268 | J53: $599.990 | K53: $549.990 | L53: 352935 | M53: 323524 | N53: 0.3 | O53: 0.3 | P53: Mix UnionX | Q53: 0.49 | R53: 0.26
A54: Innovate-K | B54: INNCAMINS-96 | C54: Gasfiteria | D54: Baroscopios | E54: Camara de Inspeccion TP9600 | F54: Cámara de Inspección de Tuberías Endoscopio Industrial TP9600 | G54: 432031 | H54: 0.44 | I54: 332669 | J54: $1.499.990 | K54: $1.299.990 | L54: 882347 | M54: 764700 | N54: 0.3 | O54: 0.3 | P54: Mix UnionX | Q54: 0.6 | R54: 0.37
A55: Innovate-K | B55: INNCAMINS-7F | C55: Gasfiteria | D55: Baroscopios | E55: Camara de Inspeccion TP9607F | F55: Cámara de Inspección de Tuberías Endoscopio Industrial TP9607F | G55: 553437 | H55: 0.41 | I55: 387734 | J55: $1.699.990 | K55: $1.599.990 | L55: 999994 | M55: 941171 | N55: 0.3 | O55: 0.3 | P55: Mix UnionX | Q55: 0.59 | R55: 0.36
A56: Innovate-K | B56: INNCAMINS-U9 | C56: Gasfiteria | D56: Baroscopios | E56: Camara de Inspeccion U9 | F56: Cámara de Inspección de Tuberías Endoscopio Industrial U9 | G56: 50149 | H56: 0.43 | I56: 38080 | J56: $159.990 | K56: $149.990 | L56: 94112 | M56: 88229 | N56: 0.3 | O56: 0.3 | P56: Mix UnionX | Q56: 0.6 | R56: 0.37
A57: Innovate-K | B57: INCAMINS92-40 | C57: Gasfiteria | D57: Baroscopios | E57: Cámaras de Inspeccion | F57: Cámara de Inspección Baroscopio con Sonda 40 Mts TP9200 | G57: 293682 | H57: 0.38 | I57: 176900 | J57: $899.990 | K57: $799.990 | L57: 529406 | M57: 470582 | N57: 0.3 | O57: 0.3 | P57: Mix UnionX | Q57: 0.56 | R57: 0.33
A58: Innovate-K | B58: 1571055493973 | C58: Hogar | D58: Accesorios para Baño | E58: Secador De Toallas Pedestal 6 Niveles | F58: Secador De Toallas Pedestal 6 Niveles | G58: 19691 | H58: 0.33 | I58: 9715 | J58: $74.990 | K58: $49.990 | L58: 44112 | M58: 29406 | N58: 0.3 | O58: 0.3 | P58: Mix UnionX | Q58: 0.53 | R58: 0.3
A59: Klip Klap | B59: 67114508251225 | C59: Instrumentos Musicales | D59: Metalofonos | E59: Metalofono Cromatico | F59: Metalofono Cromatico 25 infantil Amarillo | G59: 6081 | H59: 0.42 | I59: 8619 | J59: $29.990 | K59: $24.990 | L59: 17641 | M59: 14700 | N59: 0.3 | O59: 0.3 | P59: Descontinuado | Q59: 0.71 | R59: 0.48
A60: Klip Klap | B60: 67114505814137 | C60: Instrumentos Musicales | D60: Metalofonos | E60: Metalofono Cromatico | F60: Metalofono Cromatico 25 infantil Rosado | G60: 5894 | H60: 0.49 | I60: 8806 | J60: $29.990 | K60: $24.990 | L60: 17641 | M60: 14700 | N60: 0.3 | O60: 0.3 | P60: Descontinuado | Q60: 0.72 | R60: 0.49
A61: Levo | B61: LVCABTCLIGH-WH | C61: Accesorios | D61: Cable Cargador | E61: Cable USB Tipo-C a Lightning blanco | F61: Cable de Carga USB-C a Lightning 1 Mt Blanco LEVO | G61: 840 | H61: 0.76 | I61: 2684 | J61: $9.990 | K61: $5.990 | L61: 5876 | M61: 3524 | N61: 0.3 | O61: 0.3 | P61: Mix UnionX | Q61: 0.83 | R61: 0.6
A62: Levo | B62: LVCABTC-WH | C62: Accesorios | D62: Cable Cargador | E62: Cable USB Tipo-C a Tipo-C (5A) blanco | F62: Cable de Carga Rápida USB-C 100W 5A 1Mt Blanco LEVO | G62: 1815 | H62: 0.56 | I62: 2297 | J62: $9.990 | K62: $6.990 | L62: 5876 | M62: 4112 | N62: 0.3 | O62: 0.3 | P62: Mix UnionX | Q62: 0.69 | R62: 0.46
A63: Levo | B63: LVCABTC-BK | C63: Accesorios | D63: Cable Cargador | E63: Cable USB Tipo-C a Tipo-C (5A) negro | F63: Cable de Carga Rápida USB-C 100W 5A 1Mt Negro LEVO | G63: 1815 | H63: 0.56 | I63: 2297 | J63: $9.990 | K63: $6.990 | L63: 5876 | M63: 4112 | N63: 0.3 | O63: 0.3 | P63: Mix UnionX | Q63: 0.69 | R63: 0.46
A64: Levo | B64: 1650299083874 | C64: Accesorios | D64: Cargador Automovil | E64: Soporte Cargador Magnetico V+ | F64: Cargador Inalámbrico Carga Rapida iPhone 12/13 Auto V+ LEVO | G64: 5881 | H64: 0.33 | I64: 2937 | J64: $24.990 | K64: $14.990 | L64: 14700 | M64: 8818 | N64: 0.3 | O64: 0.3 | P64: Mix UnionX | Q64: 0.53 | R64: 0.3
A65: Levo | B65: 1652825203439 | C65: Accesorios | D65: Cargador Automovil | E65: Soporte Cargador Magnetico V01 | F65: Cargador Inalámbrico Carga Rápida Magnético Auto VO1 LEVO | G65: 6398 | H65: 0.27 | I65: 2420 | J65: $24.990 | K65: $14.990 | L65: 14700 | M65: 8818 | N65: 0.3 | O65: 0.3 | P65: Mix UnionX | Q65: 0.49 | R65: 0.26
A66: Levo | B66: LVCAR25W-WH | C66: Accesorios | D66: Cargador de Celular | E66: Cargador 25W Blanco | F66: Cargador Super Rapido De Pared 25W USB-C Blanco LEVO | G66: 2126 | H66: 0.48 | I66: 1986 | J66: $14.990 | K66: $6.990 | L66: 8818 | M66: 4112 | N66: 0.3 | O66: 0.3 | P66: Mix UnionX | Q66: 0.64 | R66: 0.41
A67: Levo | B67: LVCAR25W-BK | C67: Accesorios | D67: Cargador de Celular | E67: Cargador 25W Negro | F67: Cargador Super Rapido De Pared 25W USB-C Negro LEVO | G67: 2126 | H67: 0.48 | I67: 1986 | J67: $14.990 | K67: $6.990 | L67: 8818 | M67: 4112 | N67: 0.3 | O67: 0.3 | P67: Mix UnionX | Q67: 0.64 | R67: 0.41
A68: Levo | B68: LVCAR45W-WH | C68: Accesorios | D68: Cargador de Celular | E68: Cargador 45 W Blanco | F68: Cargador Ultra Rapido De Pared 45W USB-C Blanco LEVO | G68: 3112 | H68: 0.41 | I68: 2176 | J68: $19.990 | K68: $8.990 | L68: 11759 | M68: 5288 | N68: 0.3 | O68: 0.3 | P68: Mix UnionX | Q68: 0.59 | R68: 0.36
A69: Levo | B69: LVCAR45W-BK | C69: Accesorios | D69: Cargador de Celular | E69: Cargador 45 W Negro | F69: Cargador Ultra Rapido De Pared 45W USB-C Negro LEVO | G69: 3112 | H69: 0.41 | I69: 2176 | J69: $19.990 | K69: $8.990 | L69: 11759 | M69: 5288 | N69: 0.3 | O69: 0.3 | P69: Mix UnionX | Q69: 0.59 | R69: 0.36
A70: Levo | B70: LVHUBMP-5 | C70: Accesorios | D70: Dispositivo Multipuerto | E70: Hub multipuerto Tipo-C 5 puertos con entrada Ethernet | F70: Hub USB-C Adaptador Multipuerto 5 en 1 Macbook Windows LEVO | G70: 3786 | H70: 0.5 | I70: 3855 | J70: $14.990 | K70: $12.990 | L70: 8818 | M70: 7641 | N70: 0.3 | O70: 0.3 | P70: Mix UnionX | Q70: 0.65 | R70: 0.42
...

Sheet Stock Empresa por Bodega
A1: BDT/Stock | B1: SKU | C1: Cantidad
A2: [1000190502] Collar Triángulo Azul Talla Xs Perro Mascan | B2: 1000190502 | C2: 1.00
A3: [1513614057219] Lámpara Solar Linterna Inflable Camping Pesca Outdoor | B3: 1513614057219 | C3: 6.00
A4: [1523536647880] Hamaca Camping Pesca Outdoor Lhotse Verde Claro 270 Cm | B4: 1523536647880 | C4: 2.00
A5: [1564150627423] Audífonos Lhotse Bluetooth Inalámbrico Rm12 Blanco | B5: 1564150627423 | C5: 100.00
A6: [1564150661249] Audífonos Lhotse Bluetooth Inalámbrico Rm12 Negro | B6: 1564150661249 | C6: 100.00
A7: [1566335721736] Audífonos Lhotse Bluetooth Inalámbrico Rm12 Celeste | B7: 1566335721736 | C7: 99.00
A8: [1566849947902] Mochila Antirrobo Lhotse Gris Oscuro MA147 | B8: 1566849947902 | C8: 26.00
A9: [1571423280815] Pick-up Pad Lhotse Porta 5 Bicicletas | B9: 1571423280815 | C9: 15.00
A10: [1592492799236] Audífonos Lhotse Bluetooth Inalámbrico Rm12 Rosado | B10: 1592492799236 | C10: 100.00
A11: [1597086499840] Audífonos Lhotse RM7 Pro Inalámbrico Blanco | B11: 1597086499840 | C11: 100.00
A12: [1597098592591] Audífonos Lhotse RM7 Pro Inalámbrico Negro | B12: 1597098592591 | C12: 108.00
A13: [1615383366170] Pick-up Pad Lhotse Porta 6 Bicicletas | B13: 1615383366170 | C13: 11.00
... A61: [1909000061510] Bolsas Sanitarias Biodegradables Para Perro Mascan | B61: 1909000061510 | C61: 1.00
A62: [20-40015] Loción De Protección Solar Hidratante SPF 15 Sun Bum | B62: 20-40015 | C62: 1.00
A63: [20-45085] After Sun Cool Down Lotion Sun Bum | B63: 20-45085 | C63: 1.00
A64: [6182252] Balancio Juego De Ingenio Scratch Europe | B64: 6182252 | C64: 1.00
A65: [66800469437952] Termo de Comida Insulado Acero Inox 750 ml Rosado Simplit | B65: 66800469437952 | C65: 2.00
A66: [66800472805184] Termo de Comida Insulado Acero Inox 750 ml Gris Simplit | B66: 66800472805184 | C66: 10.00
A67: [66800506435054] Cubeta de Hielo Silicona 160 Mini Hielos Simplit | B67: 66800506435054 | C67: 8.00
A68: [66800509015029] Cubeta de Hielo Silicona 6 Hielos Redondos Simplit | B68: 66800509015029 | C68: 10.00
A69: [67327712330533] Set de 7 Contenedores Herméticos Plástico Negro Simplit | B69: 67327712330533 | C69: 74.00
A70: [67933831843970] Parlante Portatil Bluetooth Lhotse Tune Up Negro | B70: 67933831843970 | C70: 100.00
A71: [67933833934278] Parlante Portatil Bluetooth Lhotse Tune Up Rojo | B71: 67933833934278 | C71: 100.00
A72: [67933835121467] Parlante Portatil Bluetooth Lhotse Tune Up Azul | B72: 67933835121467 | C72: 10.00
A73: [67933854599885] Set 2 Vasos Cobre Moscow Mule Mojito Bar + Bombilla Simplit | B73: 67933854599885 | C73: 7.00
A74: [67933857637909] Set 6 Vasos Largo Vintage Charlotte 350ml Simplit | B74: 67933857637909 | C74: 14.00
A75: [67933859111971] Set 6 Vasos redondos Virginia 340ml Simplit | B75: 67933859111971 | C75: 12.00
... A86: [757450528058] Serum Crecimiento Pestañas Y Cejas Sheet | B86: 757450528058 | C86: 1.00
A87: [BAR-SP24] Imabars 24 piezas | B87: BAR-SP24 | C87: 7.00
A88: [BAR-SP60] Imabars 60 Piezas | B88: BAR-SP60 | C88: 1.00
A89: [CNS10150] Espuma Mousse de Limpieza Facial Caracol Natural 150 ml | B89: CNS10150 | C89: 4.00
A90: [CNS250] Crema Hidratante Antiedad Antiarrugas Caracol Natural 50 ml | B90: CNS250 | C90: 1.00
A91: [CNS550] Crema Reafirmante Restauradora Facial Caracol Natural 50 ml | B91: CNS550 | C91: 1.00
A92: [CNS630] Serum Rellenador Regenerador Facial Caracol Natural 30 ml | B92: CNS630 | C92: 3.00
A93: [CNS720] Crema Contorno de Ojos Caracol Natural 20 ml | B93: CNS720 | C93: 3.00
A94: [CNS8200] Tónico Hidratante Facial Caracol Natural 150 ml | B94: CNS8200 | C94: 1.00
A95: [DOT-020] Imadots Mini Juego Magnético | B95: DOT-020 | C95: 1.00
A96: [DOT-030] Imadots Juego Magnético | B96: DOT-030 | C96: 1.00
A97: [DYNHYDLA] Hidrolavadora eléctrica Dynamo WP 1800w 130bar 220/240V 60Hz | B97: DYNHYDLA | C97: 6.00
...

Sheet Resumen Maestra
K2: 100 | L2: 50 | M2: 10
F3: P Etiqueta | G3: PVP | H3: Costo Oferta | I3: Costo MLL | K3: Costos B2B Según volumen | O3: Margenes B2B Según volumen
F4: 0 | G4: 0 | H4: 0 | I4: 0 | K4: 0 | L4: 0.071425 | M4: 0.14286 | O4: 100+ | P4: 50 y 99 | Q4: 10 y 49
B5: Total | F5: 0 | G5: 0 | H5: 0 | I5: 0 | K5: =$H5*(1+K$4) -> 0 | L5: =$H5*(1+L$4) -> 0 | M5: =$H5*(1+M$4) -> 0 | O5: =1-K5/(G5/1.19) -> #DIV/0! | P5: =1-L5/(G5/1.19) -> #DIV/0! | Q5: =1-M5/(G5/1.19) -> #DIV/0!
B6: Bandú | C6: Accesorios de Bebe | D6: Accesorios de Bebe | E6: BDBBYCHK | F6: 0.41 | G6: 14572 | H6: 0 | I6: 0 | K6: =$H6*(1+K$4) -> 0 | L6: =$H6*(1+L$4) -> 0 | M6: =$H6*(1+M$4) -> 0 | O6: =1-K6/(G6/1.19) -> 1 | P6: =1-L6/(G6/1.19) -> 1 | Q6: =1-M6/(G6/1.19) -> 1
C7: Jueguetes de Rol | D7: Cocina y Accesorios | E7: BDCASMUÑEC | F7: 0.33 | G7: 11696 | H7: 0 | I7: 0 | K7: =$H7*(1+K$4) -> 0 | L7: =$H7*(1+L$4) -> 0 | M7: =$H7*(1+M$4) -> 0 | O7: =1-K7/(G7/1.19) -> 1 | P7: =1-L7/(G7/1.19) -> 1 | Q7: =1-M7/(G7/1.19) -> 1
E8: BDCOCGRND | F8: 0.55 | G8: 38687 | H8: 0 | I8: 0 | K8: =$H8*(1+K$4) -> 0 | L8: =$H8*(1+L$4) -> 0 | M8: =$H8*(1+M$4) -> 0 | O8: =1-K8/(G8/1.19) -> 1 | P8: =1-L8/(G8/1.19) -> 1 | Q8: =1-M8/(G8/1.19) -> 1
E9: BDCOCMEDI | F9: 0.52 | G9: 30424 | H9: 0 | I9: 0 | K9: =$H9*(1+K$4) -> 0 | L9: =$H9*(1+L$4) -> 0 | M9: =$H9*(1+M$4) -> 0 | O9: =1-K9/(G9/1.19) -> 1 | P9: =1-L9/(G9/1.19) -> 1 | Q9: =1-M9/(G9/1.19) -> 1
E10: BDCOCMIN | F10: 0.33 | G10: 3853 | H10: 0 | I10: 0 | K10: =$H10*(1+K$4) -> 0 | L10: =$H10*(1+L$4) -> 0 | M10: =$H10*(1+M$4) -> 0 | O10: =1-K10/(G10/1.19) -> 1 | P10: =1-L10/(G10/1.19) -> 1 | Q10: =1-M10/(G10/1.19) -> 1
E11: BDCOCPQMD | F11: 0.36 | G11: 14822 | H11: 0 | I11: 0 | K11: =$H11*(1+K$4) -> 0 | L11: =$H11*(1+L$4) -> 0 | M11: =$H11*(1+M$4) -> 0 | O11: =1-K11/(G11/1.19) -> 1 | P11: =1-L11/(G11/1.19) -> 1 | Q11: =1-M11/(G11/1.19) -> 1
E12: BDELECTCOC | F12: 0.42 | G12: 4171 | H12: 0 | I12: 0 | K12: =$H12*(1+K$4) -> 0 | L12: =$H12*(1+L$4) -> 0 | M12: =$H12*(1+M$4) -> 0 | O12: =1-K12/(G12/1.19) -> 1 | P12: =1-L12/(G12/1.19) -> 1 | Q12: =1-M12/(G12/1.19) -> 1
E13: BDJUESETTE | F13: 0.41 | G13: 4829 | H13: 0 | I13: 0 | K13: =$H13*(1+K$4) -> 0 | L13: =$H13*(1+L$4) -> 0 | M13: =$H13*(1+M$4) -> 0 | O13: =1-K13/(G13/1.19) -> 1 | P13: =1-L13/(G13/1.19) -> 1 | Q13: =1-M13/(G13/1.19) -> 1
E14: BDSETPAST | F14: 0.31 | G14: 3105 | H14: 0 | I14: 0 | K14: =$H14*(1+K$4) -> 0 | L14: =$H14*(1+L$4) -> 0 | M14: =$H14*(1+M$4) -> 0 | O14: =1-K14/(G14/1.19) -> 1 | P14: =1-L14/(G14/1.19) -> 1 | Q14: =1-M14/(G14/1.19) -> 1
D15: Juegos de Oficio | E15: BDSETDOC | F15: 0.46 | G15: 4048 | H15: 0 | I15: 0 | K15: =$H15*(1+K$4) -> 0 | L15: =$H15*(1+L$4) -> 0 | M15: =$H15*(1+M$4) -> 0 | O15: =1-K15/(G15/1.19) -> 1 | P15: =1-L15/(G15/1.19) -> 1 | Q15: =1-M15/(G15/1.19) -> 1
D16: Maquillaje y Belleza | E16: BDSETMAQ | F16: 0.59 | G16: 6989 | H16: 0 | I16: 0 | K16: =$H16*(1+K$4) -> 0 | L16: =$H16*(1+L$4) -> 0 | M16: =$H16*(1+M$4) -> 0 | O16: =1-K16/(G16/1.19) -> 1 | P16: =1-L16/(G16/1.19) -> 1 | Q16: =1-M16/(G16/1.19) -> 1
E17: BDTOCMD-WH | F17: 0.43 | G17: 25417 | H17: 0 | I17: 0 | K17: =$H17*(1+K$4) -> 0 | L17: =$H17*(1+L$4) -> 0 | M17: =$H17*(1+M$4) -> 0 | O17: =1-K17/(G17/1.19) -> 1 | P17: =1-L17/(G17/1.19) -> 1 | Q17: =1-M17/(G17/1.19) -> 1
C18: Juguetes de Armado | D18: Pistas y Vehiculos | E18: BDHELMAD | F18: 0.38 | G18: 8898 | H18: 0 | I18: 0 | K18: =$H18*(1+K$4) -> 0 | L18: =$H18*(1+L$4) -> 0 | M18: =$H18*(1+M$4) -> 0 | O18: =1-K18/(G18/1.19) -> 1 | P18: =1-L18/(G18/1.19) -> 1 | Q18: =1-M18/(G18/1.19) -> 1
E19: BDJUEAUT | F19: 0.44 | G19: 5118 | H19: 0 | I19: 0 | K19: =$H19*(1+K$4) -> 0 | L19: =$H19*(1+L$4) -> 0 | M19: =$H19*(1+M$4) -> 0 | O19: =1-K19/(G19/1.19) -> 1 | P19: =1-L19/(G19/1.19) -> 1 | Q19: =1-M19/(G19/1.19) -> 1
E20: BDJUETRE | F20: 0.44 | G20: 12986 | H20: 0 | I20: 0 | K20: =$H20*(1+K$4) -> 0 | L20: =$H20*(1+L$4) -> 0 | M20: =$H20*(1+M$4) -> 0 | O20: =1-K20/(G20/1.19) -> 1 | P20: =1-L20/(G20/1.19) -> 1 | Q20: =1-M20/(G20/1.19) -> 1
D21: Sets de Construccion | E21: BDMESHERRA | F21: 0.31 | G21: 9074 | H21: 0 | I21: 0 | K21: =$H21*(1+K$4) -> 0 | L21: =$H21*(1+L$4) -> 0 | M21: =$H21*(1+M$4) -> 0 | O21: =1-K21/(G21/1.19) -> 1 | P21: =1-L21/(G21/1.19) -> 1 | Q21: =1-M21/(G21/1.19) -> 1
C22: Juguetes de Motricidad | D22: Andador y Correpasillos | E22: BDANDDIDAC-GR | F22: 0.52 | G22: 15192 | H22: 0 | I22: 0 | K22: =$H22*(1+K$4) -> 0 | L22: =$H22*(1+L$4) -> 0 | M22: =$H22*(1+M$4) -> 0 | O22: =1-K22/(G22/1.19) -> 1 | P22: =1-L22/(G22/1.19) -> 1 | Q22: =1-M22/(G22/1.19) -> 1
E23: BDANDDIDAC-PK | F23: 0.5 | G23: 14751 | H23: 0 | I23: 0 | K23: =$H23*(1+K$4) -> 0 | L23: =$H23*(1+L$4) -> 0 | M23: =$H23*(1+M$4) -> 0 | O23: =1-K23/(G23/1.19) -> 1 | P23: =1-L23/(G23/1.19) -> 1 | Q23: =1-M23/(G23/1.19) -> 1
E24: BNANDCONTRU | F24: 0.43 | G24: 12706 | H24: 0 | I24: 0 | K24: =$H24*(1+K$4) -> 0 | L24: =$H24*(1+L$4) -> 0 | M24: =$H24*(1+M$4) -> 0 | O24: =1-K24/(G24/1.19) -> 1 | P24: =1-L24/(G24/1.19) -> 1 | Q24: =1-M24/(G24/1.19) -> 1
D25: Didacticos | E25: BDMBAVTHIE | F25: 0.18 | G25: 2453 | H25: 0 | I25: 0 | K25: =$H25*(1+K$4) -> 0 | L25: =$H25*(1+L$4) -> 0 | M25: =$H25*(1+M$4) -> 0 | O25: =1-K25/(G25/1.19) -> 1 | P25: =1-L25/(G25/1.19) -> 1 | Q25: =1-M25/(G25/1.19) -> 1
E26: BDMBBOESP | F26: 0.23 | G26: 1338 | H26: 0 | I26: 0 | K26: =$H26*(1+K$4) -> 0 | L26: =$H26*(1+L$4) -> 0 | M26: =$H26*(1+M$4) -> 0 | O26: =1-K26/(G26/1.19) -> 1 | P26: =1-L26/(G26/1.19) -> 1 | Q26: =1-M26/(G26/1.19) -> 1
E27: BDMBCIUMG | F27: 0.2 | G27: 2247 | H27: 0 | I27: 0 | K27: =$H27*(1+K$4) -> 0 | L27: =$H27*(1+L$4) -> 0 | M27: =$H27*(1+M$4) -> 0 | O27: =1-K27/(G27/1.19) -> 1 | P27: =1-L27/(G27/1.19) -> 1 | Q27: =1-M27/(G27/1.19) -> 1
E28: BDMBMNMRIO | F28: 0.27 | G28: 2343 | H28: 0 | I28: 0 | K28: =$H28*(1+K$4) -> 0 | L28: =$H28*(1+L$4) -> 0 | M28: =$H28*(1+M$4) -> 0 | O28: =1-K28/(G28/1.19) -> 1 | P28: =1-L28/(G28/1.19) -> 1 | Q28: =1-M28/(G28/1.19) -> 1
E29: BDMBSPAVMRIO | F29: 0.17 | G29: 2541 | H29: 0 | I29: 0 | K29: =$H29*(1+K$4) -> 0 | L29: =$H29*(1+L$4) -> 0 | M29: =$H29*(1+M$4) -> 0 | O29: =1-K29/(G29/1.19) -> 1 | P29: =1-L29/(G29/1.19) -> 1 | Q29: =1-M29/(G29/1.19) -> 1
E30: BDMESDIDAC | F30: 0.48 | G30: 14110 | H30: 0 | I30: 0 | K30: =$H30*(1+K$4) -> 0 | L30: =$H30*(1+L$4) -> 0 | M30: =$H30*(1+M$4) -> 0 | O30: =1-K30/(G30/1.19) -> 1 | P30: =1-L30/(G30/1.19) -> 1 | Q30: =1-M30/(G30/1.19) -> 1
D31: Escalada y Equilibrio | E31: BDGIMPIK | F31: 0.51 | G31: 86833 | H31: 0 | I31: 0 | K31: =$H31*(1+K$4) -> 0 | L31: =$H31*(1+L$4) -> 0 | M31: =$H31*(1+M$4) -> 0 | O31: =1-K31/(G31/1.19) -> 1 | P31: =1-L31/(G31/1.19) -> 1 | Q31: =1-M31/(G31/1.19) -> 1
E32: BDMROBLDESC | F32: 0.49 | G32: 37573 | H32: 0 | I32: 0 | K32: =$H32*(1+K$4) -> 0 | L32: =$H32*(1+L$4) -> 0 | M32: =$H32*(1+M$4) -> 0 | O32: =1-K32/(G32/1.19) -> 1 | P32: =1-L32/(G32/1.19) -> 1 | Q32: =1-M32/(G32/1.19) -> 1
B33: Total Bandú | F33: 10.67 | G33: 390776 | H33: 0 | I33: 0 | K33: =$H33*(1+K$4) -> 0 | L33: =$H33*(1+L$4) -> 0 | M33: =$H33*(1+M$4) -> 0 | O33: =1-K33/(G33/1.19) -> 1 | P33: =1-L33/(G33/1.19) -> 1 | Q33: =1-M33/(G33/1.19) -> 1
B34: Dynamo Tools | C34: Herramientas Eléctricas | D34: Otras | E34: DYNHYDLA | F34: 0.21 | G34: 8616 | H34: 0 | I34: 0 | K34: =$H34*(1+K$4) -> 0 | L34: =$H34*(1+L$4) -> 0 | M34: =$H34*(1+M$4) -> 0 | O34: =1-K34/(G34/1.19) -> 1 | P34: =1-L34/(G34/1.19) -> 1 | Q34: =1-M34/(G34/1.19) -> 1
D35: Taladro y Atornilladores | E35: DYNLLAIMP | F35: 0.27 | G35: 9381 | H35: 0 | I35: 0 | K35: =$H35*(1+K$4) -> 0 | L35: =$H35*(1+L$4) -> 0 | M35: =$H35*(1+M$4) -> 0 | O35: =1-K35/(G35/1.19) -> 1 | P35: =1-L35/(G35/1.19) -> 1 | Q35: =1-M35/(G35/1.19) -> 1
E36: DYNTALCPER | F36: 0.42 | G36: 7323 | H36: 0 | I36: 0 | K36: =$H36*(1+K$4) -> 0 | L36: =$H36*(1+L$4) -> 0 | M36: =$H36*(1+M$4) -> 0 | O36: =1-K36/(G36/1.19) -> 1 | P36: =1-L36/(G36/1.19) -> 1 | Q36: =1-M36/(G36/1.19) -> 1
E37: DYNTALIMPA | F37: 0.37 | G37: 19336 | H37: 0 | I37: 0 | K37: =$H37*(1+K$4) -> 0 | L37: =$H37*(1+L$4) -> 0 | M37: =$H37*(1+M$4) -> 0 | O37: =1-K37/(G37/1.19) -> 1 | P37: =1-L37/(G37/1.19) -> 1 | Q37: =1-M37/(G37/1.19) -> 1
E38: DYNTALPOW | F38: 0.29 | G38: 10209 | H38: 0 | I38: 0 | K38: =$H38*(1+K$4) -> 0 | L38: =$H38*(1+L$4) -> 0 | M38: =$H38*(1+M$4) -> 0 | O38: =1-K38/(G38/1.19) -> 1 | P38: =1-L38/(G38/1.19) -> 1 | Q38: =1-M38/(G38/1.19) -> 1
E39: DYNTALSCA | F39: 0.27 | G39: 3129 | H39: 0 | I39: 0 | K39: =$H39*(1+K$4) -> 0 | L39: =$H39*(1+L$4) -> 0 | M39: =$H39*(1+M$4) -> 0 | O39: =1-K39/(G39/1.19) -> 1 | P39: =1-L39/(G39/1.19) -> 1 | Q39: =1-M39/(G39/1.19) -> 1
E40: DYNTALSPER | F40: 0.44 | G40: 7766 | H40: 0 | I40: 0 | K40: =$H40*(1+K$4) -> 0 | L40: =$H40*(1+L$4) -> 0 | M40: =$H40*(1+M$4) -> 0 | O40: =1-K40/(G40/1.19) -> 1 | P40: =1-L40/(G40/1.19) -> 1 | Q40: =1-M40/(G40/1.19) -> 1
B41: Total Dynamo Tools | F41: 2.27 | G41: 65760 | H41: 0 | I41: 0 | K41: =$H41*(1+K$4) -> 0 | L41: =$H41*(1+L$4) -> 0 | M41: =$H41*(1+M$4) -> 0 | O41: =1-K41/(G41/1.19) -> 1 | P41: =1-L41/(G41/1.19) -> 1 | Q41: =1-M41/(G41/1.19) -> 1
...

Sheet Urban Maestra
F2: INFORMACION CLIENTE | H2: INFORMACION UNIONX | K2: INFORMACION CLIENTE
F3: UnionX | G3: Cliente | H3: UnionX | K3: Precios Ciente | M3: Costo Cliente | O3: Margen | Q3: Status
A4: CLUSTER | B4: Marca | C4: Sku | D4: Seccion | E4: Familia | F4: Grupo | G4: Descripcion | H4: Costo MLL | I4: ROI | J4: Utilidad UnionX | K4: P Etiqueta | L4: PVP Oferta | M4: Costo | N4: Costo Oferta | O4: Margen Master | P4: Margen Oferta | Q4: Status MLL | R4: MG FRONT | S4: MG COMISION | T4: PVP Oferta Competitivo | U4: Caja Master
A5: A | B5: Atmosphera | C5: 209063 | D5: Alfombras | E5: Alfombras | F5: Alfombra Yute redonda impresa malakite 118 cm | G5: Alfombra Yute redonda impresa malakite 118 cm | H5: 18761 | I5: 0.36 | J5: 10644 | K5: 69990 | L5: 49990 | M5: 41171 | N5: 29406 | O5: 0.3 | P5: 0.3 | Q5: Mix MLL | R5: 0.55 | S5: 0.32
A6: A | B6: Atmosphera | C6: 168857Z | D6: Alfombras | E6: Alfombras | F6: Alfombra Yute Borde Blanco 120 x 170 cm | G6: Alfombra Yute Borde Blanco 120 x 170 cm | H6: 27796 | I6: 0.37 | J6: 16316 | K6: 89990 | L6: 74990 | M6: 52935 | N6: 44112 | O6: 0.3 | P6: 0.3 | Q6: Mix MLL | R6: 0.56 | S6: 0.33
A7: A | B7: Atmosphera | C7: 201982 | D7: Alfombras | E7: Alfombras | F7: Alfombra Yute de pasillo 80 cm x 200 cm | G7: Alfombra Yute de pasillo 80 cm x 200 cm | H7: 20840 | I7: 0.36 | J7: 11507 | K7: 69990 | L7: 54990 | M7: 41171 | N7: 32347 | O7: 0.3 | P7: 0.3 | Q7: Mix MLL | R7: 0.55 | S7: 0.32
A8: A | B8: Atmosphera | C8: 202016 | D8: Alfombras | E8: Alfombras | F8: Alfombra de exterior/interior Luka 120 cm x 170 cm | G8: Alfombra de exterior/interior Luka 120 cm x 170 cm | H8: 27796 | I8: 0.37 | J8: 16316 | K8: 99990 | L8: 74990 | M8: 58818 | N8: 44112 | O8: 0.3 | P8: 0.3 | Q8: Mix MLL | R8: 0.56 | S8: 0.33
A9: A | B9: Atmosphera | C9: 202017 | D9: Alfombras | E9: Alfombras | F9: Alfombra de exterior/interior Luka 160 cm x 230 cm | G9: Alfombra de exterior/interior Luka 160 cm x 230 cm | H9: 48623 | I9: 0.36 | J9: 27841 | K9: 149990 | L9: 129990 | M9: 88229 | N9: 76465 | O9: 0.3 | P9: 0.3 | Q9: Mix MLL | R9: 0.55 | S9: 0.32
A10: A | B10: Atmosphera | C10: 184924 | D10: Muebles deco | E10: Muebles deco | F10: Rack Tv 2 puertas Colva | G10: Rack Tv 2 puertas Colva | H10: 126000 | I10: 0.33 | J10: 62229 | K10: 349990 | L10: 319990 | M10: 205876 | N10: 188229 | O10: 0.3 | P10: 0.3 | Q10: Mix MLL | R10: 0.53 | S10: 0.3
A11: A | B11: Atmosphera | C11: 179010 | D11: Muebles deco | E11: Muebles deco | F11: Respaldo Aoni Ratan 160 cm x 140 cm | G11: Respaldo Aoni Ratan 160 cm x 140 cm | H11: 103950 | I11: 0.35 | J11: 54868 | K11: 299990 | L11: 269990 | M11: 176465 | N11: 158818 | O11: 0.3 | P11: 0.3 | Q11: Mix MLL | R11: 0.54 | S11: 0.31
A12: A | B12: Atmosphera | C12: 192954 | D12: Muebles deco | E12: Muebles deco | F12: Respaldo Ronnie Ratan 160 cm x 100 cm | G12: Respaldo Ronnie Ratan 160 cm x 100 cm | H12: 103950 | I12: 0.35 | J12: 54868 | K12: 299990 | L12: 269990 | M12: 176465 | N12: 158818 | O12: 0.3 | P12: 0.3 | Q12: Mix MLL | R12: 0.54 | S12: 0.31
A13: A | B13: Atmosphera | C13: 197700 | D13: Muebles deco | E13: Muebles deco | F13: Velador Yute 1 cajon Rayo | G13: Velador Yute 1 cajon Rayo | H13: 55440 | I13: 0.37 | J13: 32789 | K13: 149990 | L13: 149990 | M13: 88229 | N13: 88229 | O13: 0.3 | P13: 0.3 | Q13: Mix MLL | R13: 0.56 | S13: 0.33
A14: A | B14: Atmosphera | C14: 179012 | D14: Muebles deco | E14: Muebles deco | F14: Velador Ratan 1 cajon Aoni | G14: Velador Ratan 1 cajon Aoni | H14: 63000 | I14: 0.33 | J14: 31112 | K14: 149990 | L14: 159990 | M14: 88229 | N14: 94112 | O14: 0.3 | P14: 0.3 | Q14: Mix MLL | R14: 0.53 | S14: 0.3
A15: A | B15: Atmosphera | C15: 114516A | D15: Muebles deco | E15: Muebles deco | F15: Velador 1 cajon blanco Chrysa | G15: Velador 1 cajon blanco Chrysa | H15: 63000 | I15: 0.33 | J15: 31112 | K15: 149990 | L15: 159990 | M15: 88229 | N15: 94112 | O15: 0.3 | P15: 0.3 | Q15: Mix MLL | R15: 0.53 | S15: 0.3
A16: A | B16: Atmosphera | C16: 197703 | D16: Muebles deco | E16: Muebles deco | F16: Comoda doble 6 cajones Rayo | G16: Comoda doble 6 cajones Rayo | H16: 207900 | I16: 0.29 | J16: 86212 | K16: 699990 | L16: 499990 | M16: 411759 | N16: 294112 | O16: 0.3 | P16: 0.3 | Q16: Mix MLL | R16: 0.51 | S16: 0.28
A17: A | B17: Atmosphera | C17: 179098 | D17: Muebles deco | E17: Muebles deco | F17: Comoda 12 cajones Ajay | G17: Comoda 12 cajones Ajay | H17: 441000 | I17: 0.25 | J17: 147229 | K17: 1299990 | L17: 999990 | M17: 764700 | N17: 588229 | O17: 0.3 | P17: 0.3 | Q17: Mix MLL | R17: 0.48 | S17: 0.25
A18: A | B18: Atmosphera | C18: 123174 | D18: Muebles deco | E18: Muebles deco | F18: Lampara de pie tripode madera negra 145 cm Runo | G18: Lampara de pie tripode madera negra 145 cm Runo | H18: 27796 | I18: 0.32 | J18: 13375 | K18: 99990 | L18: 69990 | M18: 58818 | N18: 41171 | O18: 0.3 | P18: 0.3 | Q18: Mix MLL | R18: 0.53 | S18: 0.3
A19: A | B19: Atmosphera | C19: 190675 | D19: Muebles deco | E19: Muebles deco | F19: Lampara de pie arco bambu natural 173 cm Liby | G19: Lampara de pie arco bambu natural 173 cm Liby | H19: 65986 | I19: 0.34 | J19: 34008 | K19: 199990 | L19: 169990 | M19: 117641 | N19: 99994 | O19: 0.3 | P19: 0.3 | Q19: Mix MLL | R19: 0.54 | S19: 0.31
A20: A | B20: Atmosphera | C20: 182433 | D20: Muebles deco | E20: Muebles deco | F20: Lampra de pie arco metal 180 cm Rahe | G20: Lampra de pie arco metal 180 cm Rahe | H20: 48623 | I20: 0.36 | J20: 27841 | K20: 149990 | L20: 129990 | M20: 88229 | N20: 76465 | O20: 0.3 | P20: 0.3 | Q20: Mix MLL | R20: 0.55 | S20: 0.32
A21: A | B21: Atmosphera | C21: 181024L | D21: Cojines | E21: Cojines | F21: Cojin reciclado etnico 45X45 cm | G21: Cojin reciclado etnico 45X45 cm | H21: 9034 | I21: 0.39 | J21: 5666 | K21: 29990 | L21: 24990 | M21: 17641 | N21: 14700 | O21: 0.3 | P21: 0.3 | Q21: Mix MLL | R21: 0.57 | S21: 0.34
A22: A | B22: Atmosphera | C22: 185268 | D22: Cojines | E22: Cojines | F22: Cojin flecos y lazoi 45X45 cm | G22: Cojin flecos y lazoi 45X45 cm | H22: 9034 | I22: 0.39 | J22: 5666 | K22: 29990 | L22: 24990 | M22: 17641 | N22: 14700 | O22: 0.3 | P22: 0.3 | Q22: Mix MLL | R22: 0.57 | S22: 0.34
A23: A | B23: 5Five | C23: 111539A | D23: Bandejas | E23: Bandejas | F23: Bandeja Rectangular Angular 44X29 cm Bambú 5Five | G23: Bandeja Rectangular Angular 44X29 cm Bambú 5Five | H23: 4613 | I23: 0.4 | J23: 3028 | K23: 14990 | L23: 12990 | M23: 8818 | N23: 7641 | O23: 0.3 | P23: 0.3 | Q23: Mix MLL | R23: 0.58 | S23: 0.35
A24: A | B24: 5Five | C24: 161016 | D24: Espejos | E24: Espejos | F24: Joyero De Bambu Con Espejo 15X15X9 Cm 5Five | G24: Joyero De Bambu Con Espejo 15X15X9 Cm 5Five | H24: 6212 | I24: 0.38 | J24: 3782 | K24: 19990 | L24: 16990 | M24: 11759 | N24: 9994 | O24: 0.3 | P24: 0.3 | Q24: Descontinuado | R24: 0.56 | S24: 0.33
A25: A | B25: 5Five | C25: 160479 | D25: Muebles deco | E25: Muebles deco | F25: Banca Madera Mix Café 105 X 34 X 50 cm 5 Five | G25: Banca Madera Mix Café 105 X 34 X 50 cm 5 Five | H25: 33402 | I25: 0.37 | J25: 19533 | K25: 119990 | L25: 89990 | M25: 70582 | N25: 52935 | O25: 0.3 | P25: 0.3 | Q25: Mix MLL | R25: 0.56 | S25: 0.33
A26: A | B26: 5Five | C26: 134515 | D26: Cafeteras | E26: Cafeteras | F26: Cafetera Italiana acero 6 Tazas Negro 5Five | G26: Cafetera Italiana acero 6 Tazas Negro 5Five | H26: 6186 | I26: 0.34 | J26: 3220 | K26: 19990 | L26: 15990 | M26: 11759 | N26: 9406 | O26: 0.3 | P26: 0.3 | Q26: Descontinuado | R26: 0.54 | S26: 0.31
A27: A | B27: Atmosphera | C27: 172476 | D27: Alfombras | E27: Alfombras | F27: Alfombra Natura De Yute Beige 160X230 cm Atmosphera | G27: Alfombra Natura De Yute Beige 160X230 cm Atmosphera | H27: 62249 | I27: 0.33 | J27: 30098 | K27: 199990 | L27: 156990 | M27: 117641 | N27: 92347 | O27: 0.3 | P27: 0.3 | Q27: Mix MLL | R27: 0.53 | S27: 0.3
A28: A | B28: Atmosphera | C28: 194340 | D28: Alfombras | E28: Alfombras | F28: Alfombra Yute Redonda 160 cm Atmosphera | G28: Alfombra Yute Redonda 160 cm Atmosphera | H28: 32134 | I28: 0.33 | J28: 15507 | K28: 149990 | L28: 80990 | M28: 88229 | N28: 47641 | O28: 0.3 | P28: 0.3 | Q28: Mix MLL | R28: 0.53 | S28: 0.3
A29: A | B29: Atmosphera | C29: 168857D | D29: Alfombras | E29: Alfombras | F29: Alfombra Yute Natural 120X170 cm Atmosphera | G29: Alfombra Yute Natural 120X170 cm Atmosphera | H29: 28756 | I29: 0.33 | J29: 14179 | K29: 89990 | L29: 72990 | M29: 52935 | N29: 42935 | O29: 0.3 | P29: 0.3 | Q29: Mix MLL | R29: 0.53 | S29: 0.3
A30: A | B30: Atmosphera | C30: 168857J | D30: Alfombras | E30: Alfombras | F30: Alfombra Yute Borde Negro 120X170 cm Atmosphera | G30: Alfombra Yute Borde Negro 120X170 cm Atmosphera | H30: 28881 | I30: 0.33 | J30: 14054 | K30: 89990 | L30: 72990 | M30: 52935 | N30: 42935 | O30: 0.3 | P30: 0.3 | Q30: Mix MLL | R30: 0.53 | S30: 0.3
A31: A | B31: Atmosphera | C31: 181000 | D31: Alfombras | E31: Alfombras | F31: Alfombra Yute Redonda 120 cm Atmosphera | G31: Alfombra Yute Redonda 120 cm Atmosphera | H31: 16629 | I31: 0.34 | J31: 8659 | K31: 69990 | L31: 42990 | M31: 41171 | N31: 25288 | O31: 0.3 | P31: 0.3 | Q31: Mix MLL | R31: 0.54 | S31: 0.31
A32: A | B32: Atmosphera | C32: 146295J | D32: Alfombras | E32: Alfombras | F32: Alfombra Yute Redonda Con Borde Negro 120 cm Atmosphera | G32: Alfombra Yute Redonda Con Borde Negro 120 cm Atmosphera | H32: 16631 | I32: 0.34 | J32: 8657 | K32: 69990 | L32: 42990 | M32: 41171 | N32: 25288 | O32: 0.3 | P32: 0.3 | Q32: Mix MLL | R32: 0.54 | S32: 0.31
A33: A | B33: Atmosphera | C33: 157266 | D33: Cajas decorativas | E33: Cajas decorativas | F33: Costurero Oria 30 Cm De Largo Atmosphera | G33: Costurero Oria 30 Cm De Largo Atmosphera | H33: 8512 | I33: 0.34 | J33: 4423 | K33: 24990 | L33: 21990 | M33: 14700 | N33: 12935 | O33: 0.3 | P33: 0.3 | Q33: Mix MLL | R33: 0.54 | S33: 0.31
A34: A | B34: Atmosphera | C34: 178520 | D34: Cojines | E34: Cojines | F34: Cojín Macrame 30X50 cm Atmosphera | G34: Cojín Macrame 30X50 cm Atmosphera | H34: 8024 | I34: 0.35 | J34: 4323 | K34: 22990 | L34: 20990 | M34: 13524 | N34: 12347 | O34: 0.3 | P34: 0.3 | Q34: Mix MLL | R34: 0.55 | S34: 0.32
A35: A | B35: Atmosphera | C35: 172496 | D35: Cojines | E35: Cojines | F35: Cojin Algodón Y Polister Sand Cop 40X40 cm Atmosphera | G35: Cojin Algodón Y Polister Sand Cop 40X40 cm Atmosphera | H35: 6475 | I35: 0.15 | J35: 1166 | K35: 16990 | L35: 12990 | M35: 9994 | N35: 7641 | O35: 0.3 | P35: 0.3 | Q35: Mix MLL | R35: 0.41 | S35: 0.18
A36: A | B36: Atmosphera | C36: 172462N | D36: Cojines | E36: Cojines | F36: Cojin Inca Algodón Y Poliester 40X40 cm Terracota Atmosphera | G36: Cojin Inca Algodón Y Poliester 40X40 cm Terracota Atmosphera | H36: 4353 | I36: 0.43 | J36: 3288 | K36: 16990 | L36: 12990 | M36: 9994 | N36: 7641 | O36: 0.3 | P36: 0.3 | Q36: Mix MLL | R36: 0.6 | S36: 0.37
A37: A | B37: Atmosphera | C37: 179422B | D37: Espejos | E37: Espejos | F37: Espejo Redondo Alice 76 cm Con Borde Metal Dorado Atmosphera | G37: Espejo Redondo Alice 76 cm Con Borde Metal Dorado Atmosphera | H37: 21871 | I37: 0.34 | J37: 11064 | K37: 69990 | L37: 55990 | M37: 41171 | N37: 32935 | O37: 0.3 | P37: 0.3 | Q37: Descontinuado | R37: 0.54 | S37: 0.31
A38: A | B38: Atmosphera | C38: 200200B | D38: Espejos | E38: Espejos | F38: Espejo Redondo Alice 38 cm Borde Metal Dorado Atmosphera | G38: Espejo Redondo Alice 38 cm Borde Metal Dorado Atmosphera | H38: 6118 | I38: 0.35 | J38: 3288 | K38: 19990 | L38: 15990 | M38: 11759 | N38: 9406 | O38: 0.3 | P38: 0.3 | Q38: Descontinuado | R38: 0.54 | S38: 0.31
A39: A | B39: Atmosphera | C39: 116415C | D39: Luces Decorativas | E39: Luces Decorativas | F39: Guirnalda Led 10 Bolas Blanco 165 cm Atmosphera | G39: Guirnalda Led 10 Bolas Blanco 165 cm Atmosphera | H39: 2377 | I39: 0.42 | J39: 1735 | K39: 9990 | L39: 6990 | M39: 5876 | N39: 4112 | O39: 0.3 | P39: 0.3 | Q39: Descontinuado | R39: 0.6 | S39: 0.37
A40: A | B40: Atmosphera | C40: 179073 | D40: Mesas de centro | E40: Mesas de centro | F40: Mesa De Centro Solen 4 Cajones 110 X 60 X 47 cm Atmosphera | G40: Mesa De Centro Solen 4 Cajones 110 X 60 X 47 cm Atmosphera | H40: 92067 | I40: 0.32 | J40: 43809 | K40: 299990 | L40: 230990 | M40: 176465 | N40: 135876 | O40: 0.3 | P40: 0.3 | Q40: Descontinuado | R40: 0.53 | S40: 0.3
A41: A | B41: Atmosphera | C41: 157210 | D41: Mesas de centro | E41: Mesas de centro | F41: Mesa De Centro Damian 4 Cajones 110 X 60 X 45 cm Atmosphera | G41: Mesa De Centro Damian 4 Cajones 110 X 60 X 45 cm Atmosphera | H41: 95941 | I41: 0.32 | J41: 45818 | K41: 299990 | L41: 240990 | M41: 176465 | N41: 141759 | O41: 0.3 | P41: 0.3 | Q41: Descontinuado | R41: 0.53 | S41: 0.3
...

Sheet Productos y Categorizacion
A1: Marca | B1: SKU | C1: Producto | D1: Categoría macro | E1: Categoría padre | F1: Categoría hijo | G1: Categoría comercial | H1: In/out | I1: Pack | J1: Estado marca | K1: Proveedor
A2: 5 Surprise | B2: 32935 | C2: Bola 5 Sorpresas Serie My Mini Baby | D2: Kids | E2: Figuras y muñecos | F2: Figuras y muñecos | G2: Nuevo | H2: out | I2: No | J2: Out | K2: Ansaldo
A3: 5Five | B3: 120200A | C3: Mug De Café 350 Cc Gris - Acero Inoxidable | D3: Home | E3: Mundo Café | F3: Termos líquidos | G3: Nuevo | H3: out | I3: No | J3: In | K3: Urban
A4: 5Five | B4: 120200B | C4: Mug De Cafe Negro Acero Inoxidable 350 Cc | D4: Home | E4: Mundo Café | F4: Termos líquidos | G4: Nuevo | H4: out | I4: No | J4: In | K4: Urban
A5: 5Five | B5: 174713 | C5: Pulverizador Vidrio 450 Cc Color Ambar | D5: Home | E5: Deco | F5: Utensilios de aseo | G5: Nuevo | H5: out | I5: No | J5: In | K5: Urban
A6: 5Five | B6: 179742 | C6: Exprimidor rallado en 4 en 1 5Five | D6: Home | E6: Cristalería y Bar | F6: Bar | G6: Nuevo | H6: out | I6: No | J6: In | K6: Urban
A7: 5Five | B7: 120040 | C7: Bandeja Antideslizante Gris 45X32 Cm 5Five | D7: Kids | E7: Deco | F7: Bandejas | G7: Nuevo | H7: out | I7: No | J7: In | K7: Urban
A8: 5Five | B8: 189720 | C8: Bandeja cuadrada Kord 35cm beige mimbre | D8: Home | E8: Deco | F8: Bandejas | G8: Nuevo | H8: out | I8: No | J8: In | K8: Urban
A9: 5Five | B9: 169228 | C9: Bandeja De Metal Mayaj | D9: Home | E9: Deco | F9: Bandejas | G9: Nuevo | H9: out | I9: No | J9: In | K9: Urban
A10: 5Five | B10: 111539A | C10: Bandeja Rectangular Angular 44X29 cm Bambú | D10: Home | E10: Deco | F10: Bandejas | G10: Nuevo | H10: in | I10: No | J10: In | K10: Urban
A11: 5Five | B11: 162085 | C11: Bandeja redonda de 35 cm Jacynte mimbre | D11: Home | E11: Deco | F11: Bandejas | G11: Nuevo | H11: in | I11: No | J11: In | K11: Urban
A12: 5Five | B12: 189717 | C12: Bandeja redonda kord 40 cm mimbre | D12: Home | E12: Deco | F12: Bandejas | G12: Nuevo | H12: in | I12: No | J12: In | K12: Urban
A13: 5Five | B13: 161016 | C13: Joyero De Bambu Con Espejo 15X15X9 Cm | D13: Home | E13: Deco | F13: Joyeros | G13: Nuevo | H13: out | I13: No | J13: In | K13: Urban
A14: 5Five | B14: 189699 | C14: Set De 2 Tablas De Cortas Bambu 5Five | D14: Home | E14: Deco | F14: Tablas | G14: Nuevo | H14: out | I14: No | J14: In | K14: Urban
A15: 5Five | B15: 540724263 | C15: Set De 3 Tablas De Cortar De Bambu Secret de Gourmet | D15: Home | E15: Deco | F15: Tablas | G15: Nuevo | H15: out | I15: No | J15: In | K15: Urban
A16: 5Five | B16: 154350 | C16: Botella Vidrio Con Diseños Y Tapa Acero Inox 500 Ml | D16: Home | E16: Hidratación | F16: Botellas de Agua | G16: Nuevo | H16: out | I16: No | J16: In | K16: Urban
A17: 5Five | B17: 146604 | C17: Cuchillo Carnicero Acero Inox Y Mango Acacia 24 Cm | D17: Home | E17: Menaje de Cocina | F17: Cuchilleria | G17: Nuevo | H17: out | I17: No | J17: In | K17: Urban
A18: 5Five | B18: 146607 | C18: Cuchillo Chef Acero Inox Con Mango Acacia 35 Cm | D18: Home | E18: Menaje de Cocina | F18: Cuchilleria | G18: Nuevo | H18: out | I18: No | J18: In | K18: Urban
A19: 5Five | B19: 120307 | C19: Cuchillo Cocina Chef 33 Cm | D19: Home | E19: Menaje de Cocina | F19: Cuchilleria | G19: Nuevo | H19: out | I19: No | J19: In | K19: Urban
A20: 5Five | B20: 120306 | C20: Cuchillo Cocina Santoku 25 Cm | D20: Home | E20: Menaje de Cocina | F20: Cuchilleria | G20: Nuevo | H20: out | I20: No | J20: In | K20: Urban
A21: 5Five | B21: 151268 | C21: Set De Cuchillos Marmol | D21: Home | E21: Menaje de Cocina | F21: Cuchilleria | G21: Nuevo | H21: out | I21: No | J21: In | K21: Urban
A22: 5Five | B22: 151170 | C22: Taco De 11 Cuchillos Con Afilador Y Tijera Cocina | D22: Home | E22: Menaje de Cocina | F22: Cuchilleria | G22: Nuevo | H22: out | I22: No | J22: In | K22: Urban
... A35: 5Five | B35: 146589 | C35: Set De Utensilios De Cocina Nylon 4 Piezas | D35: Home | E35: Menaje de Cocina | F35: Utensilios de cocina | G35: Nuevo | H35: out | I35: No | J35: In | K35: Urban
A36: 5Five | B36: 100145A | C36: Soplete Cocina a Gas | D36: Home | E36: Menaje de Cocina | F36: Utensilios de cocina | G36: Nuevo | H36: out | I36: No | J36: In | K36: Urban
A37: 5Five | B37: 103700 | C37: Toma Olla De Silicona | D37: Home | E37: Menaje de Cocina | F37: Utensilios de cocina | G37: Nuevo | H37: out | I37: No | J37: In | K37: Urban
A38: 5Five | B38: 119695 | C38: Triturador De Papas Acero Inox 26 X 8 X 8 Cm | D38: Home | E38: Menaje de Cocina | F38: Utensilios de cocina | G38: Nuevo | H38: out | I38: No | J38: In | K38: Urban
A39: 5Five | B39: 124599 | C39: Mat Silicona Repostería 38 X 28 Cc | D39: Home | E39: Menaje de Cocina | F39: Utensilios repostería | G39: Nuevo | H39: out | I39: No | J39: In | K39: Urban
A40: 5Five | B40: 151190 | C40: Set 10 Cortadores/Moldes De Galletas | D40: Home | E40: Menaje de Cocina | F40: Utensilios repostería | G40: Nuevo | H40: out | I40: No | J40: In | K40: Urban
A41: 5Five | B41: 124576 | C41: Set 6 Moldes Silicona Para Respostería | D41: Home | E41: Menaje de Cocina | F41: Utensilios repostería | G41: Nuevo | H41: out | I41: No | J41: In | K41: Urban
A42: 5Five | B42: 160479 | C42: Banca Madera Mix Café 105 X 34 X 50 cm 5 Five | D42: Home | E42: Muebles deco | F42: Bancas | G42: Nuevo | H42: in | I42: No | J42: In | K42: Urban
A43: 5Five | B43: 160479A | C43: Banca Madera Mix Gris 105 X 50 X 34 | D43: Home | E43: Muebles deco | F43: Bancas | G43: Nuevo | H43: out | I43: No | J43: In | K43: Urban
A44: 5Five | B44: 189646 | C44: Mueble Bar con soporte para 25 botellas Aliaj 5Five | D44: Home | E44: Muebles deco | F44: Bares | G44: Nuevo | H44: in | I44: No | J44: In | K44: Urban
A45: 5Five | B45: 185017 | C45: Escritorio Cierna 120x53x77 Cm | D45: Home | E45: Muebles deco | F45: Escritorios | G45: Nuevo | H45: out | I45: No | J45: In | K45: Urban
A46: 5Five | B46: 181327 | C46: Escritorio Drawers 120 X 76 X 60 Cm | D46: Home | E46: Muebles deco | F46: Escritorios | G46: Nuevo | H46: out | I46: No | J46: In | K46: Urban
A47: 5Five | B47: 189634 | C47: Rack De Vino De Bambú Para 12 Botellas | D47: Home | E47: Muebles deco | F47: Repisas | G47: Nuevo | H47: out | I47: No | J47: In | K47: Urban
A48: 5Five | B48: 120075N | C48: Cafetera Prensa Francesa 800 cc Vidrio 5Five | D48: Home | E48: Mundo Café | F48: Cafeteras | G48: Nuevo | H48: in | I48: No | J48: In | K48: Urban
A49: 5Five | B49: 120075G | C49: Cafetera Prensa Francesa 800 cc Vidrio 5Five | D49: Home | E49: Mundo Café | F49: Cafeteras | G49: Nuevo | H49: in | I49: No | J49: In | K49: Urban
A50: 5Five | B50: 120075R | C50: Cafetera Prensa Francesa 800 cc Vidrio 5Five | D50: Home | E50: Mundo Café | F50: Cafeteras | G50: Nuevo | H50: out | I50: No | J50: In | K50: Urban
A51: 5Five | B51: 120075 | C51: Cafetera Presna Francesa 800 Cc Vidrio Y Polipropileno Colores | D51: Home | E51: Mundo Café | F51: Cafeteras | G51: Nuevo | H51: out | I51: No | J51: In | K51: Urban
A52: 5Five | B52: 188441 | C52: Soporte Y 6 Tazas De Cafe De Vidrio 100 Cc | D52: Home | E52: Mundo Café | F52: Tazas | G52: Nuevo | H52: out | I52: No | J52: In | K52: Urban
...

Sheet Empresa
A1: Empresa | B1: Canal
A2: Cliente Bice | B2: Banco Bice
A3: Bravium Chile SPA | B3: Bravium
A4: COMERCIAL GIANNY GIOVANNY CAPONA PALACIOS | B4: Casa de la Carcasa
A5: Electrónica Casa Royal LTDA. | B5: Casa Royal
A6: Celmedia Fidelización SPA | B6: Celmedia
A7: Cliente Linio | B7: CMR
A8: AUTOBAHN S A | B8: Concesionarios autos
A9: Servicio Automotriz Automec Limitada | B9: Concesionarios autos
A10: Felicity 360 SpA | B10: Corporativo
A11: VUELVO AL SUR SPA | B11: Corporativo
A12: MW2 CHILE MARKETING SPA | B12: Corporativo
... A149: Sanchez y Cia. | B149: Ferretería Higuerillas

Sheet CanalxKam
A1: Canal | B1: Tipo Negocio | C1: KAM | D1: Estado Canal
A2: Abc | B2: Marketplace | C2: Trini | D2: In
A3: Andesgear | B3: Marketplace | C3: NA | D3: out
A4: Banco Bice | B4: Fidelización | C4: Clau | D4: In
A5: Banco Scotiabank | B5: Fidelización | C5: NA | D5: out
A6: BazarED | B6: Marketplace | C6: Nicole | D6: In
A7: Betterfly | B7: Fidelización | C7: NA | D7: out
A8: Bodega | B8: Distribución | C8: NA | D8: out
A9: Bravium | B9: Fidelización | C9: Nicole | D9: out
A10: Celmedia | B10: Fidelización | C10: Trini | D10: In
A11: Cencosud | B11: Garantía extendida | C11: NA | D11: out
A12: Cmr | B12: Fidelización | C12: Nacha | D12: In
... A125: Speedreams | B125: Corporativo | C125: Erich | D125: In

Sheet Stock
A1: CA1/Stock | B1: Sku | C1: Costo Neto | D1: 154,165
A2: [1-MA-M] Bolsa Courier Compostable Materiactiva | B2: 1-MA-M | C2: 22280 | D2: 69
A3: [10001374] Campanilla Bicicleta Nutcase Baby Shark | B3: 10001374 | C3: 6490 | D3: 1
A4: [1000190502] Collar Triángulo Azul Talla Xs Perro Mascan | B4: 1000190502 | C4: 0 | D4: 6
A5: [1000190507] Collar Triángulo Naranja Tallas XS Perro Mascan | B5: 1000190507 | C5: 0 | D5: 3
A6: [1000190521] Collar Triángulo Fucsia Talla Xs Perro Mascan | B6: 1000190521 | C6: 0 | D6: 3
A7: [1000190602] Collar Triángulo Azul Talla S Perro Mascan | B7: 1000190602 | C7: 0 | D7: 3
A8: [1000190607] Collar Triángulo Naranja Tallas S Perro Mascan | B8: 1000190607 | C8: 0 | D8: 3
A9: [1000190621] Collar Triángulo Fucsia Talla S Perro Mascan | B9: 1000190621 | C9: 0 | D9: 3
A10: [1000190702] Collar Triángulo Azul Talla M Perro Mascan | B10: 1000190702 | C10: 0 | D10: 2
A11: [1000190707] Collar Triángulo Naranja Tallas M Perro Mascan | B11: 1000190707 | C11: 0 | D11: 4
A12: [1000190721] Collar Triángulo Fucsia Talla M Perro Mascan | B12: 1000190721 | C12: 0 | D12: 3
A13: [1000190802] Collar Triángulo Azul Talla L Perro Mascan | B13: 1000190802 | C13: 0 | D13: 4
A14: [1000190807] Collar Triángulo Naranja Tallas L Perro Mascan | B14: 1000190807 | C14: 0 | D14: 4
... A116: [1481123937937] Ampolleta Auto Halógena Biolight 9007 65/55w White 12v | B116: 1481123937937 | C116: 0 | D116: 5
A117: [1483452520904] Sensor Anti Fatiga Driver State Monitor | B117: #N/A | C117: #N/A | D117: 10
A118: [1496183099853] Cámara Deportiva 4k Lhotse H1 Video Con Accesorios | B118: 1496183099853 | C118: 17422 | D118: 123
A119: [1507904554106] Android 2111 | B119: 1507904554106 | C119: 1200 | D119: 1
A120: [1513100019184] Estabilizador De Cámaras Universales Portátil | B120: 1513100019184 | C120: 6665 | D120: 3
A121: [1513614057219] Lámpara Solar Linterna Inflable Camping Pesca Outdoor | B121: 1513614057219 | C121: 3379 | D121: 266
A122: [1513615220412] TV Streaming Device Chromecast | B122: 1513615220412 | C122: 8987 | D122: 36
A123: [1513615272195] Android Tv Box Mxq Pro 4K | B123: 1513615272195 | C123: 13329 | D123: 6
A124: [1514379781861] Monkey Toy Interactivo Azul | B124: 1514379781861 | C124: 3505 | D124: 1
A125: [1523536647880] Hamaca Camping Pesca Outdoor Lhotse Verde Claro 270 Cm | B125: 1523536647880 | C125: 11468 | D125: 123
A126: [1535543463599] Parrilla Portátil Carbón Kettle Roja 17'' | B126: 1535543463599 | C126: 17356 | D126: 12
A127: [1535566560027] Reloj Smartwatch Lhotse P10 Blanco | B127: 1535566560027 | C127: 7128 | D127: 9
