Workbook

Sheet Fechas Cargas
A1: RESUMEN DE FECHAS DE CARGA — Shipping Plan September V.02 vs Plan B Steven (Jun 30th)
A2: Generado: 30-06-2026 | Tránsito Shenzhen 52d, Ningbo 45d | CRD→ETD 7d | ETA Puerto→Bodega 7d
A4: Embarque | B4: Puerto | C4: SKUs | D4: Qty total | E4: CRD | F4: ETD | G4: ETA Puerto | H4: ETA Bodega
A5: IMP OP 350-26 40HQ | B5: NB | C5: 16 | D5: 14750 | E5: 46203 | F5: 46210 | G5: 46255 | H5: 46262
A6: SZ-04,40HQ | B6: SZ | C6: 36 | D6: 8450 | E6: 46204 | F6: 46211 | G6: 46263 | H6: 46270
A7: SZ-03-08,40HQ | B7: SZ | C7: 17 | D7: 6056 | E7: 46208 | F7: 46215 | G7: 46267 | H7: 46274
A8: NB-01 | B8: NB | C8: 3 | D8: 3006 | E8: 46223 | F8: 46230 | G8: 46275 | H8: 46282
A9: SZ-01(623) | B9: SZ | C9: 5 | D9: 2050 | E9: 46218 | F9: 46225 | G9: 46277 | H9: 46284
A10: SZ-02(623) | B10: SZ | C10: 13 | D10: 3708 | E10: 46244 | F10: 46251 | G10: 46303 | H10: 46310

Sheet Summary
A1: SHIPPING PLAN — September Arrival (Rest Items)
A2: Demand: Transit SEP 26 | 40HQ Freight: USD 6,250 | Arrival Deadline: Aug 31, 2026 | Source: Shipping Plan-Jun.18th (3.Rest items) + manual inclusion AeroFlow Beige Dryer (specs HD4 base)
A4: CLASSIFICATION
A5: Category | B5: Units | C5: % Demand | D5: Action
A6: ✅ SHIP | B6: 11300 | C6: 63.0% | D6: Include in plan
A7: ⏳ PEND. CONFIRMATION | B7: 600 | C7: 3.3% | D7: Wait for supplier OK
A8: ⚠️ MISSING (not in Rest items) | B8: 6050 | C8: 33.7% | D8: Manage production / other source
A9: TOTAL DEMAND | B9: 17950 | C9: 100% | D9: CHECK = 0 (balances)
A11: WITHIN 'SHIP' — deadline compliance Aug 31
A12: Sub-category | B12: Units | C12: Detail
A13: 🟢 Arrives on time (ETA ≤ Aug 31) | B13: 4950 | C13: Container SZ-01
A14: 🔴 Arrives late (ETA > Aug 31) | B14: 6350 | C14: Containers SZ-02, SZ-03, NB-01 — supplier CRD later than deadline
A16: CONTAINERS
A17: Cont# | B17: CRD | C17: ETA | D17: CBM | E17: Occup% | F17: USD Value | G17: Freight% | H17: SKUs | I17: Units | J17: Arrives Aug 31?
A18: SZ-01 | B18: 2026-06-30 | C18: 2026-08-31 | D18: 65.9 | E18: 96.9% | F18: 41710 | G18: 12.5% | H18: 20 | I18: 4200 | J18: YES
A19: SZ-02 | B19: 2026-06-30 | C19: 2026-08-31 | D19: 6.7 | E19: 9.9% | F19: 3225 | G19: 64.9% | H19: 2 | I19: 750 | J19: YES
A20: SZ-03 | B20: 2026-07-15 | C20: 2026-09-15 | D20: 67.9 | E20: 99.9% | F20: 24434 | G20: 19.6% | H20: 5 | I20: 1850 | J20: NO — late
A21: SZ-04 | B21: 2026-07-31 | C21: 2026-10-01 | D21: 29.9 | E21: 44.0% | F21: 18350 | G21: 24.5% | H21: 5 | I21: 1500 | J21: NO — late
A22: NB-01 | B22: 2026-07-20 | C22: 2026-09-10 | D22: 39.3 | E22: 57.8% | F22: 72000 | G22: 7.6% | H22: 2 | I22: 3000 | J22: NO — late
A24: PLAN AJUSTADO (Steven Plan B-Jun.30th)
A25: Embarque Steven | B25: Origen | C25: CRD | D25: ETD | E25: ETA Puerto | F25: ETA Bodega | G25: SKUs UnionX V02 | H25: Uds UnionX V02 | J25: ¿A tiempo (≤31-ago-26)?
A26: SZ-04,40HQ | B26: SZ | C26: 46202 | D26: 46209 | E26: 46261 | F26: 46268 | G26: =COUNTIFS(Detail_SZ!N:N,A26)+COUNTIFS(Detail_NB!N:N,A26)+COUNTIFS(Late_Arrivals!J:J,A26)+COUNTIFS(Pend_Confirmation!G:G,A26)+COUNTIFS(Missing!G:G,A26) -> 10 | H26: =SUMIFS(Detail_SZ!M:M,Detail_SZ!N:N,A26)+SUMIFS(Detail_NB!M:M,Detail_NB!N:N,A26)+SUMIFS(Late_Arrivals!I:I,Late_Arrivals!J:J,A26)+SUMIFS(Pend_Confirmation!F:F,Pend_Confirmation!G:G,A26)+SUMIFS(Missing!F:F,Missing!G:G,A26) -> 1870 | I26: 1300 | J26: NO
A27: SZ-03-08,40HQ | B27: SZ | C27: 46208 | D27: 46215 | E27: 46267 | F27: 46274 | G27: =COUNTIFS(Detail_SZ!N:N,A27)+COUNTIFS(Detail_NB!N:N,A27)+COUNTIFS(Late_Arrivals!J:J,A27)+COUNTIFS(Pend_Confirmation!G:G,A27)+COUNTIFS(Missing!G:G,A27) -> 15 | H27: =SUMIFS(Detail_SZ!M:M,Detail_SZ!N:N,A27)+SUMIFS(Detail_NB!M:M,Detail_NB!N:N,A27)+SUMIFS(Late_Arrivals!I:I,Late_Arrivals!J:J,A27)+SUMIFS(Pend_Confirmation!F:F,Pend_Confirmation!G:G,A27)+SUMIFS(Missing!F:F,Missing!G:G,A27) -> 3202 | I27: 2952 | J27: NO
A28: SZ-01(623) | B28: SZ | C28: 46218 | D28: 46225 | E28: 46277 | F28: 46284 | G28: =COUNTIFS(Detail_SZ!N:N,A28)+COUNTIFS(Detail_NB!N:N,A28)+COUNTIFS(Late_Arrivals!J:J,A28)+COUNTIFS(Pend_Confirmation!G:G,A28)+COUNTIFS(Missing!G:G,A28) -> 9 | H28: =SUMIFS(Detail_SZ!M:M,Detail_SZ!N:N,A28)+SUMIFS(Detail_NB!M:M,Detail_NB!N:N,A28)+SUMIFS(Late_Arrivals!I:I,Late_Arrivals!J:J,A28)+SUMIFS(Pend_Confirmation!F:F,Pend_Confirmation!G:G,A28)+SUMIFS(Missing!F:F,Missing!G:G,A28) -> 3400 | I28: 1550 | J28: NO
A29: SZ-02(623) | B29: SZ | C29: 46244 | D29: 46251 | E29: 46303 | F29: 46310 | G29: =COUNTIFS(Detail_SZ!N:N,A29)+COUNTIFS(Detail_NB!N:N,A29)+COUNTIFS(Late_Arrivals!J:J,A29)+COUNTIFS(Pend_Confirmation!G:G,A29)+COUNTIFS(Missing!G:G,A29) -> 19 | H29: =SUMIFS(Detail_SZ!M:M,Detail_SZ!N:N,A29)+SUMIFS(Detail_NB!M:M,Detail_NB!N:N,A29)+SUMIFS(Late_Arrivals!I:I,Late_Arrivals!J:J,A29)+SUMIFS(Pend_Confirmation!F:F,Pend_Confirmation!G:G,A29)+SUMIFS(Missing!F:F,Missing!G:G,A29) -> 4686 | I29: 2758 | J29: NO
A30: IMP OP 350-26 40HQ | B30: SZ | G30: =COUNTIFS(Detail_SZ!N:N,A30)+COUNTIFS(Detail_NB!N:N,A30)+COUNTIFS(Late_Arrivals!J:J,A30)+COUNTIFS(Pend_Confirmation!G:G,A30)+COUNTIFS(Missing!G:G,A30) -> 2 | H30: =SUMIFS(Detail_SZ!M:M,Detail_SZ!N:N,A30)+SUMIFS(Detail_NB!M:M,Detail_NB!N:N,A30)+SUMIFS(Late_Arrivals!I:I,Late_Arrivals!J:J,A30)+SUMIFS(Pend_Confirmation!F:F,Pend_Confirmation!G:G,A30)+SUMIFS(Missing!F:F,Missing!G:G,A30) -> 300 | I30: 0 | J30: NO
A31: NB-01 | B31: NB | C31: 46223 | D31: 46230 | E31: 46275 | F31: 46282 | G31: =COUNTIFS(Detail_SZ!N:N,A31)+COUNTIFS(Detail_NB!N:N,A31)+COUNTIFS(Late_Arrivals!J:J,A31)+COUNTIFS(Pend_Confirmation!G:G,A31)+COUNTIFS(Missing!G:G,A31) -> 7 | H31: =SUMIFS(Detail_SZ!M:M,Detail_SZ!N:N,A31)+SUMIFS(Detail_NB!M:M,Detail_NB!N:N,A31)+SUMIFS(Late_Arrivals!I:I,Late_Arrivals!J:J,A31)+SUMIFS(Pend_Confirmation!F:F,Pend_Confirmation!G:G,A31)+SUMIFS(Missing!F:F,Missing!G:G,A31) -> 8014 | I31: 3006 | J31: NO
A32: NB-02 | B32: NB | C32: 46249 | D32: 46256 | E32: 46301 | F32: 46308 | G32: =COUNTIFS(Detail_SZ!N:N,A32)+COUNTIFS(Detail_NB!N:N,A32)+COUNTIFS(Late_Arrivals!J:J,A32)+COUNTIFS(Pend_Confirmation!G:G,A32)+COUNTIFS(Missing!G:G,A32) -> 13 | H32: =SUMIFS(Detail_SZ!M:M,Detail_SZ!N:N,A32)+SUMIFS(Detail_NB!M:M,Detail_NB!N:N,A32)+SUMIFS(Late_Arrivals!I:I,Late_Arrivals!J:J,A32)+SUMIFS(Pend_Confirmation!F:F,Pend_Confirmation!G:G,A32)+SUMIFS(Missing!F:F,Missing!G:G,A32) -> 1155 | J32: NO
A33: IMP OP 351-26 40HQ | B33: SZ | C33: 46213 | D33: 46220 | E33: 46272 | F33: 46279 | G33: =COUNTIFS(Detail_SZ!N:N,A33)+COUNTIFS(Detail_NB!N:N,A33)+COUNTIFS(Late_Arrivals!J:J,A33)+COUNTIFS(Pend_Confirmation!G:G,A33)+COUNTIFS(Missing!G:G,A33) -> 6 | H33: =SUMIFS(Detail_SZ!M:M,Detail_SZ!N:N,A33)+SUMIFS(Detail_NB!M:M,Detail_NB!N:N,A33)+SUMIFS(Late_Arrivals!I:I,Late_Arrivals!J:J,A33)+SUMIFS(Pend_Confirmation!F:F,Pend_Confirmation!G:G,A33)+SUMIFS(Missing!F:F,Missing!G:G,A33) -> 725 | J33: NO
A34: TOTAL
A36: STOCK NO ASIGNADO (Rest items)
A37: Rest items | G37: 29 | H37: 10057

Sheet Detail_SZ
A1: Container | B1: CRD | C1: ETA | D1: Order No | E1: Brand | F1: SKU | G1: Description | H1: Units | I1: CBM | J1: USD Value | K1: Need to pay? | L1: Late? | M1: Cantidad cargada | N1: Embarque (Steven) | O1: CRD | P1: ETD | Q1: ETA Puerto | R1: ETA Bodega
A2: SZ-01 | B2: 2026-06-30 | C2: 2026-08-31 | D2: 518 | E2: Simplit | F2: SIMCUPGL-30 | G2: Set de Cuchillería 30 pcs Cubiertos Acero Inoxidable Puglia | H2: 250 | I2: 0.753 | J2: 1860 | M2: 500 | N2: SZ-03-08,40HQ | O2: =IFERROR(INDEX(Refs_Embarques!$F$5:$F$11,MATCH(N2,Refs_Embarques!$A$5:$A$11,0)),"") -> 46208 | P2: =IFERROR(INDEX(Refs_Embarques!$G$5:$G$11,MATCH(N2,Refs_Embarques!$A$5:$A$11,0)),"") -> 46215 | Q2: =IFERROR(INDEX(Refs_Embarques!$H$5:$H$11,MATCH(N2,Refs_Embarques!$A$5:$A$11,0)),"") -> 46267 | R2: =IFERROR(INDEX(Refs_Embarques!$I$5:$I$11,MATCH(N2,Refs_Embarques!$A$5:$A$11,0)),"") -> 46274
A3: SZ-01 | B3: 2026-06-30 | C3: 2026-08-31 | D3: 407 | E3: Simplit | F3: SIMJULZOPO-30 | G3: Juego de Loza 30 pcs Cerámica Oporto Simplit | H3: 300 | I3: 17.377 | J3: 5880 | M3: 300 | N3: SZ-03-08,40HQ | O3: =IFERROR(INDEX(Refs_Embarques!$F$5:$F$11,MATCH(N3,Refs_Embarques!$A$5:$A$11,0)),"") -> 46208 | P3: =IFERROR(INDEX(Refs_Embarques!$G$5:$G$11,MATCH(N3,Refs_Embarques!$A$5:$A$11,0)),"") -> 46215 | Q3: =IFERROR(INDEX(Refs_Embarques!$H$5:$H$11,MATCH(N3,Refs_Embarques!$A$5:$A$11,0)),"") -> 46267 | R3: =IFERROR(INDEX(Refs_Embarques!$I$5:$I$11,MATCH(N3,Refs_Embarques!$A$5:$A$11,0)),"") -> 46274
A4: SZ-01 | B4: 2026-06-30 | C4: 2026-08-31 | D4: 407 | E4: Simplit | F4: SIMJULZSIE-30 | G4: Juego Loza Cerámica 30 pcs Siena 6 personas Simplit | H4: 300 | I4: 15.175 | J4: 4740 | M4: 300 | N4: SZ-03-08,40HQ | O4: =IFERROR(INDEX(Refs_Embarques!$F$5:$F$11,MATCH(N4,Refs_Embarques!$A$5:$A$11,0)),"") -> 46208 | P4: =IFERROR(INDEX(Refs_Embarques!$G$5:$G$11,MATCH(N4,Refs_Embarques!$A$5:$A$11,0)),"") -> 46215 | Q4: =IFERROR(INDEX(Refs_Embarques!$H$5:$H$11,MATCH(N4,Refs_Embarques!$A$5:$A$11,0)),"") -> 46267 | R4: =IFERROR(INDEX(Refs_Embarques!$I$5:$I$11,MATCH(N4,Refs_Embarques!$A$5:$A$11,0)),"") -> 46274
A5: SZ-01 | B5: 2026-06-30 | C5: 2026-08-31 | D5: 528 | E5: Levo | F5: LVPANTOTPUB-43 | G5: Pantalla Totem Publicitario 43" Touch Android Wifi Usb LEVO | H5: 8 | I5: 1.635 | J5: 3040 | M5: 8 | N5: SZ-03-08,40HQ | O5: =IFERROR(INDEX(Refs_Embarques!$F$5:$F$11,MATCH(N5,Refs_Embarques!$A$5:$A$11,0)),"") -> 46208 | P5: =IFERROR(INDEX(Refs_Embarques!$G$5:$G$11,MATCH(N5,Refs_Embarques!$A$5:$A$11,0)),"") -> 46215 | Q5: =IFERROR(INDEX(Refs_Embarques!$H$5:$H$11,MATCH(N5,Refs_Embarques!$A$5:$A$11,0)),"") -> 46267 | R5: =IFERROR(INDEX(Refs_Embarques!$I$5:$I$11,MATCH(N5,Refs_Embarques!$A$5:$A$11,0)),"") -> 46274
A6: SZ-01 | B6: 2026-06-30 | C6: 2026-08-31 | D6: 528 | E6: Lhotse | F6: LHBIGMU-PPN | G6: Vaso Termico Tumbler Acero Inox Antiderrame 1180ml Lilac Lhotse | H6: 100 | I6: 0.537 | J6: 330 | M6: 100 | N6: SZ-04,40HQ | O6: =IFERROR(INDEX(Refs_Embarques!$F$5:$F$11,MATCH(N6,Refs_Embarques!$A$5:$A$11,0)),"") -> 46204 | P6: =IFERROR(INDEX(Refs_Embarques!$G$5:$G$11,MATCH(N6,Refs_Embarques!$A$5:$A$11,0)),"") -> 46211 | Q6: =IFERROR(INDEX(Refs_Embarques!$H$5:$H$11,MATCH(N6,Refs_Embarques!$A$5:$A$11,0)),"") -> 46263 | R6: =IFERROR(INDEX(Refs_Embarques!$I$5:$I$11,MATCH(N6,Refs_Embarques!$A$5:$A$11,0)),"") -> 46270
A7: SZ-01 | B7: 2026-06-30 | C7: 2026-08-31 | D7: 528 | E7: Lhotse | F7: LHBIGMU-BKN | G7: Vaso Termico Tumbler Acero Inox Antiderrame 1180ml Black Lhotse | H7: 100 | I7: 0.537 | J7: 360 | M7: 100 | N7: SZ-04,40HQ | O7: =IFERROR(INDEX(Refs_Embarques!$F$5:$F$11,MATCH(N7,Refs_Embarques!$A$5:$A$11,0)),"") -> 46204 | P7: =IFERROR(INDEX(Refs_Embarques!$G$5:$G$11,MATCH(N7,Refs_Embarques!$A$5:$A$11,0)),"") -> 46211 | Q7: =IFERROR(INDEX(Refs_Embarques!$H$5:$H$11,MATCH(N7,Refs_Embarques!$A$5:$A$11,0)),"") -> 46263 | R7: =IFERROR(INDEX(Refs_Embarques!$I$5:$I$11,MATCH(N7,Refs_Embarques!$A$5:$A$11,0)),"") -> 46270
A8: SZ-01 | B8: 2026-06-30 | C8: 2026-08-31 | D8: 528 | E8: Simplit | F8: 67933856404072 | G8: Set 6 Vasos Corto Vintage Charlotte 200ml Simplit | H8: 300 | I8: 1.081 | J8: 945 | M8: 300 | N8: SZ-04,40HQ | O8: =IFERROR(INDEX(Refs_Embarques!$F$5:$F$11,MATCH(N8,Refs_Embarques!$A$5:$A$11,0)),"") -> 46204 | P8: =IFERROR(INDEX(Refs_Embarques!$G$5:$G$11,MATCH(N8,Refs_Embarques!$A$5:$A$11,0)),"") -> 46211 | Q8: =IFERROR(INDEX(Refs_Embarques!$H$5:$H$11,MATCH(N8,Refs_Embarques!$A$5:$A$11,0)),"") -> 46263 | R8: =IFERROR(INDEX(Refs_Embarques!$I$5:$I$11,MATCH(N8,Refs_Embarques!$A$5:$A$11,0)),"") -> 46270
A9: SZ-01 | B9: 2026-06-30 | C9: 2026-08-31 | D9: 528 | E9: Simplit | F9: 67933857637909 | G9: Set 6 Vasos Largo Vintage Charlotte 350ml Simplit | H9: 300 | I9: 1.622 | J9: 1110 | M9: 300 | N9: SZ-04,40HQ | O9: =IFERROR(INDEX(Refs_Embarques!$F$5:$F$11,MATCH(N9,Refs_Embarques!$A$5:$A$11,0)),"") -> 46204 | P9: =IFERROR(INDEX(Refs_Embarques!$G$5:$G$11,MATCH(N9,Refs_Embarques!$A$5:$A$11,0)),"") -> 46211 | Q9: =IFERROR(INDEX(Refs_Embarques!$H$5:$H$11,MATCH(N9,Refs_Embarques!$A$5:$A$11,0)),"") -> 46263 | R9: =IFERROR(INDEX(Refs_Embarques!$I$5:$I$11,MATCH(N9,Refs_Embarques!$A$5:$A$11,0)),"") -> 46270
A10: SZ-01 | B10: 2026-06-30 | C10: 2026-08-31 | D10: 528 | E10: Simplit | F10: 67933863068841 | G10: Set 6 Vaso Copa Cerveza Collins 420ml Simplit | H10: 200 | I10: 1.848 | J10: 790 | M10: 200 | N10: SZ-04,40HQ | O10: =IFERROR(INDEX(Refs_Embarques!$F$5:$F$11,MATCH(N10,Refs_Embarques!$A$5:$A$11,0)),"") -> 46204 | P10: =IFERROR(INDEX(Refs_Embarques!$G$5:$G$11,MATCH(N10,Refs_Embarques!$A$5:$A$11,0)),"") -> 46211 | Q10: =IFERROR(INDEX(Refs_Embarques!$H$5:$H$11,MATCH(N10,Refs_Embarques!$A$5:$A$11,0)),"") -> 46263 | R10: =IFERROR(INDEX(Refs_Embarques!$I$5:$I$11,MATCH(N10,Refs_Embarques!$A$5:$A$11,0)),"") -> 46270
A11: SZ-01 | B11: 2026-06-30 | C11: 2026-08-31 | D11: 1019 | E11: Simplit | F11: SIMBOWSIE-4 | G11: Set 4 Bowls Cerámica 8,5cm Siena Simplit | H11: 100 | I11: 0.598 | J11: 206 | M11: 102 | N11: SZ-03-08,40HQ | O11: =IFERROR(INDEX(Refs_Embarques!$F$5:$F$11,MATCH(N11,Refs_Embarques!$A$5:$A$11,0)),"") -> 46208 | P11: =IFERROR(INDEX(Refs_Embarques!$G$5:$G$11,MATCH(N11,Refs_Embarques!$A$5:$A$11,0)),"") -> 46215 | Q11: =IFERROR(INDEX(Refs_Embarques!$H$5:$H$11,MATCH(N11,Refs_Embarques!$A$5:$A$11,0)),"") -> 46267 | R11: =IFERROR(INDEX(Refs_Embarques!$I$5:$I$11,MATCH(N11,Refs_Embarques!$A$5:$A$11,0)),"") -> 46274
A12: SZ-01 | B12: 2026-06-30 | C12: 2026-08-31 | D12: 1019 | E12: Simplit | F12: SIMJULZAMA-24 | G12: Juego Loza Cerámica 24 pcs Amalfi Simplit | H12: 250 | I12: 10.64 | J12: 3088 | M12: 250 | N12: SZ-03-08,40HQ | O12: =IFERROR(INDEX(Refs_Embarques!$F$5:$F$11,MATCH(N12,Refs_Embarques!$A$5:$A$11,0)),"") -> 46208 | P12: =IFERROR(INDEX(Refs_Embarques!$G$5:$G$11,MATCH(N12,Refs_Embarques!$A$5:$A$11,0)),"") -> 46215 | Q12: =IFERROR(INDEX(Refs_Embarques!$H$5:$H$11,MATCH(N12,Refs_Embarques!$A$5:$A$11,0)),"") -> 46267 | R12: =IFERROR(INDEX(Refs_Embarques!$I$5:$I$11,MATCH(N12,Refs_Embarques!$A$5:$A$11,0)),"") -> 46274
A13: SZ-01 | B13: 2026-06-30 | C13: 2026-08-31 | D13: 528 | E13: Simplit | F13: 1652825295706 | G13: Cafetera Italiana Negra Granito 12 Tazas Simplit | H13: 200 | I13: 1.34 | J13: 1120 | M13: 200 | N13: SZ-02(623) | O13: =IFERROR(INDEX(Refs_Embarques!$F$5:$F$11,MATCH(N13,Refs_Embarques!$A$5:$A$11,0)),"") -> 46244 | P13: =IFERROR(INDEX(Refs_Embarques!$G$5:$G$11,MATCH(N13,Refs_Embarques!$A$5:$A$11,0)),"") -> 46251 | Q13: =IFERROR(INDEX(Refs_Embarques!$H$5:$H$11,MATCH(N13,Refs_Embarques!$A$5:$A$11,0)),"") -> 46303 | R13: =IFERROR(INDEX(Refs_Embarques!$I$5:$I$11,MATCH(N13,Refs_Embarques!$A$5:$A$11,0)),"") -> 46310
A14: SZ-01 | B14: 2026-06-30 | C14: 2026-08-31 | D14: 528 | E14: Simplit | F14: 1627418180602 | G14: Especiero Condimentos Giratorio Metálico 16 Frascos Simplit | H14: 200 | I14: 2.48 | J14: 1070 | M14: 200 | N14: SZ-02(623) | O14: =IFERROR(INDEX(Refs_Embarques!$F$5:$F$11,MATCH(N14,Refs_Embarques!$A$5:$A$11,0)),"") -> 46244 | P14: =IFERROR(INDEX(Refs_Embarques!$G$5:$G$11,MATCH(N14,Refs_Embarques!$A$5:$A$11,0)),"") -> 46251 | Q14: =IFERROR(INDEX(Refs_Embarques!$H$5:$H$11,MATCH(N14,Refs_Embarques!$A$5:$A$11,0)),"") -> 46303 | R14: =IFERROR(INDEX(Refs_Embarques!$I$5:$I$11,MATCH(N14,Refs_Embarques!$A$5:$A$11,0)),"") -> 46310
A15: SZ-01 | B15: 2026-06-30 | C15: 2026-08-31 | D15: 1222 | E15: Simplit | F15: SIMTAZSIE-4 | G15: Set 4 Tazas Cerámica 330ml Siena Simplit | H15: 192 | I15: 0.778 | J15: 192 | M15: 192 | N15: SZ-03-08,40HQ | O15: =IFERROR(INDEX(Refs_Embarques!$F$5:$F$11,MATCH(N15,Refs_Embarques!$A$5:$A$11,0)),"") -> 46208 | P15: =IFERROR(INDEX(Refs_Embarques!$G$5:$G$11,MATCH(N15,Refs_Embarques!$A$5:$A$11,0)),"") -> 46215 | Q15: =IFERROR(INDEX(Refs_Embarques!$H$5:$H$11,MATCH(N15,Refs_Embarques!$A$5:$A$11,0)),"") -> 46267 | R15: =IFERROR(INDEX(Refs_Embarques!$I$5:$I$11,MATCH(N15,Refs_Embarques!$A$5:$A$11,0)),"") -> 46274
A16: SZ-01 | B16: 2026-06-30 | C16: 2026-08-31 | D16: 528 | E16: Simplit | F16: 1660859171584 | G16: Espumador de Leche 4 en 1 Negro Simplit | H16: 400 | I16: 2.31 | J16: 5740 | M16: 400 | N16: SZ-03-08,40HQ | O16: =IFERROR(INDEX(Refs_Embarques!$F$5:$F$11,MATCH(N16,Refs_Embarques!$A$5:$A$11,0)),"") -> 46208 | P16: =IFERROR(INDEX(Refs_Embarques!$G$5:$G$11,MATCH(N16,Refs_Embarques!$A$5:$A$11,0)),"") -> 46215 | Q16: =IFERROR(INDEX(Refs_Embarques!$H$5:$H$11,MATCH(N16,Refs_Embarques!$A$5:$A$11,0)),"") -> 46267 | R16: =IFERROR(INDEX(Refs_Embarques!$I$5:$I$11,MATCH(N16,Refs_Embarques!$A$5:$A$11,0)),"") -> 46274
A17: SZ-01 | B17: 2026-06-30 | C17: 2026-08-31 | D17: 528 | E17: Simplit | F17: 68432930518995 | G17: Espumador de Leche 4 en 1 Blanco Simplit | H17: 200 | I17: 1.155 | J17: 2870 | M17: 200 | N17: SZ-03-08,40HQ | O17: =IFERROR(INDEX(Refs_Embarques!$F$5:$F$11,MATCH(N17,Refs_Embarques!$A$5:$A$11,0)),"") -> 46208 | P17: =IFERROR(INDEX(Refs_Embarques!$G$5:$G$11,MATCH(N17,Refs_Embarques!$A$5:$A$11,0)),"") -> 46215 | Q17: =IFERROR(INDEX(Refs_Embarques!$H$5:$H$11,MATCH(N17,Refs_Embarques!$A$5:$A$11,0)),"") -> 46267 | R17: =IFERROR(INDEX(Refs_Embarques!$I$5:$I$11,MATCH(N17,Refs_Embarques!$A$5:$A$11,0)),"") -> 46274
A18: SZ-01 | B18: 2026-06-30 | C18: 2026-08-31 | D18: 528 | E18: Levo | F18: 67327559384453 | G18: Cámara HD Auto D3 Frontal, Interior y Trasera LEVO | H18: 100 | I18: 0.188 | J18: 1340 | M18: 100 | N18: SZ-03-08,40HQ | O18: =IFERROR(INDEX(Refs_Embarques!$F$5:$F$11,MATCH(N18,Refs_Embarques!$A$5:$A$11,0)),"") -> 46208 | P18: =IFERROR(INDEX(Refs_Embarques!$G$5:$G$11,MATCH(N18,Refs_Embarques!$A$5:$A$11,0)),"") -> 46215 | Q18: =IFERROR(INDEX(Refs_Embarques!$H$5:$H$11,MATCH(N18,Refs_Embarques!$A$5:$A$11,0)),"") -> 46267 | R18: =IFERROR(INDEX(Refs_Embarques!$I$5:$I$11,MATCH(N18,Refs_Embarques!$A$5:$A$11,0)),"") -> 46274
A19: SZ-01 | B19: 2026-06-30 | C19: 2026-08-31 | D19: 528 | E19: Simplit | F19: 1629726091782 | G19: Set 12 Utensilios De Cocina Silicona Calipso Simplit | H19: 300 | I19: 1.781 | J19: 1530 | M19: 300 | N19: SZ-03-08,40HQ | O19: =IFERROR(INDEX(Refs_Embarques!$F$5:$F$11,MATCH(N19,Refs_Embarques!$A$5:$A$11,0)),"") -> 46208 | P19: =IFERROR(INDEX(Refs_Embarques!$G$5:$G$11,MATCH(N19,Refs_Embarques!$A$5:$A$11,0)),"") -> 46215 | Q19: =IFERROR(INDEX(Refs_Embarques!$H$5:$H$11,MATCH(N19,Refs_Embarques!$A$5:$A$11,0)),"") -> 46267 | R19: =IFERROR(INDEX(Refs_Embarques!$I$5:$I$11,MATCH(N19,Refs_Embarques!$A$5:$A$11,0)),"") -> 46274
A20: SZ-01 | B20: 2026-06-30 | C20: 2026-08-31 | D20: 528 | E20: Lhotse | F20: 1623703861303 | G20: Bolso Deportivo Lhotse Duffel 30 Lts Bag Negro | H20: 300 | I20: 1.548 | J20: 2850 | M20: 300 | N20: SZ-03-08,40HQ | O20: =IFERROR(INDEX(Refs_Embarques!$F$5:$F$11,MATCH(N20,Refs_Embarques!$A$5:$A$11,0)),"") -> 46208 | P20: =IFERROR(INDEX(Refs_Embarques!$G$5:$G$11,MATCH(N20,Refs_Embarques!$A$5:$A$11,0)),"") -> 46215 | Q20: =IFERROR(INDEX(Refs_Embarques!$H$5:$H$11,MATCH(N20,Refs_Embarques!$A$5:$A$11,0)),"") -> 46267 | R20: =IFERROR(INDEX(Refs_Embarques!$I$5:$I$11,MATCH(N20,Refs_Embarques!$A$5:$A$11,0)),"") -> 46274
A21: SZ-01 | B21: 2026-06-30 | C21: 2026-08-31 | D21: 528 | E21: Lhotse | F21: 1571423280815 | G21: Pick-up Pad Lhotse Porta 5 Bicicletas | H21: 100 | I21: 2.52 | J21: 2650 | M21: 100 | N21: SZ-02(623) | O21: =IFERROR(INDEX(Refs_Embarques!$F$5:$F$11,MATCH(N21,Refs_Embarques!$A$5:$A$11,0)),"") -> 46244 | P21: =IFERROR(INDEX(Refs_Embarques!$G$5:$G$11,MATCH(N21,Refs_Embarques!$A$5:$A$11,0)),"") -> 46251 | Q21: =IFERROR(INDEX(Refs_Embarques!$H$5:$H$11,MATCH(N21,Refs_Embarques!$A$5:$A$11,0)),"") -> 46303 | R21: =IFERROR(INDEX(Refs_Embarques!$I$5:$I$11,MATCH(N21,Refs_Embarques!$A$5:$A$11,0)),"") -> 46310
A22: SZ-02 | B22: 2026-06-30 | C22: 2026-08-31 | D22: 528 | E22: Simplit | F22: SIMVASLARGINE | G22: Set 6 Vasos Largos 460ml Vidrio Ginebra Simplit | H22: 300 | I22: 2.199 | J22: 1155 | M22: 300 | N22: SZ-02(623) | O22: =IFERROR(INDEX(Refs_Embarques!$F$5:$F$11,MATCH(N22,Refs_Embarques!$A$5:$A$11,0)),"") -> 46244 | P22: =IFERROR(INDEX(Refs_Embarques!$G$5:$G$11,MATCH(N22,Refs_Embarques!$A$5:$A$11,0)),"") -> 46251 | Q22: =IFERROR(INDEX(Refs_Embarques!$H$5:$H$11,MATCH(N22,Refs_Embarques!$A$5:$A$11,0)),"") -> 46303 | R22: =IFERROR(INDEX(Refs_Embarques!$I$5:$I$11,MATCH(N22,Refs_Embarques!$A$5:$A$11,0)),"") -> 46310
A23: SZ-02 | B23: 2026-06-30 | C23: 2026-08-31 | D23: 528 | E23: Xroad | F23: 1660859424566 | G23: Carpa Funda Cubre Auto Impermeable Premium con Felpa Xroad | H23: 450 | I23: 4.535 | J23: 2070 | M23: 450 | N23: SZ-02(623) | O23: =IFERROR(INDEX(Refs_Embarques!$F$5:$F$11,MATCH(N23,Refs_Embarques!$A$5:$A$11,0)),"") -> 46244 | P23: =IFERROR(INDEX(Refs_Embarques!$G$5:$G$11,MATCH(N23,Refs_Embarques!$A$5:$A$11,0)),"") -> 46251 | Q23: =IFERROR(INDEX(Refs_Embarques!$H$5:$H$11,MATCH(N23,Refs_Embarques!$A$5:$A$11,0)),"") -> 46303 | R23: =IFERROR(INDEX(Refs_Embarques!$I$5:$I$11,MATCH(N23,Refs_Embarques!$A$5:$A$11,0)),"") -> 46310
A24: SZ-03 | B24: 2026-07-15 | C24: 2026-09-15 | D24: 528 | E24: Simplit | F24: 1630369674271 | G24: Cafetera Prensa Francesa Negra 600 ml Simplit | H24: 150 | I24: 0.492 | J24: 442 | L24: LATE | M24: 150 | N24: SZ-01(623) | O24: =IFERROR(INDEX(Refs_Embarques!$F$5:$F$11,MATCH(N24,Refs_Embarques!$A$5:$A$11,0)),"") -> 46218 | P24: =IFERROR(INDEX(Refs_Embarques!$G$5:$G$11,MATCH(N24,Refs_Embarques!$A$5:$A$11,0)),"") -> 46225 | Q24: =IFERROR(INDEX(Refs_Embarques!$H$5:$H$11,MATCH(N24,Refs_Embarques!$A$5:$A$11,0)),"") -> 46277 | R24: =IFERROR(INDEX(Refs_Embarques!$I$5:$I$11,MATCH(N24,Refs_Embarques!$A$5:$A$11,0)),"") -> 46284
A25: SZ-03 | B25: 2026-07-15 | C25: 2026-09-15 | D25: 528 | E25: Simplit | F25: SIMOREXBAS-WD | G25: Organizador Cubiertos Expandible Madera Acasia Basel Simplit | H25: 300 | I25: 2.599 | J25: 1530 | L25: LATE | M25: 300 | N25: SZ-02(623) | O25: =IFERROR(INDEX(Refs_Embarques!$F$5:$F$11,MATCH(N25,Refs_Embarques!$A$5:$A$11,0)),"") -> 46244 | P25: =IFERROR(INDEX(Refs_Embarques!$G$5:$G$11,MATCH(N25,Refs_Embarques!$A$5:$A$11,0)),"") -> 46251 | Q25: =IFERROR(INDEX(Refs_Embarques!$H$5:$H$11,MATCH(N25,Refs_Embarques!$A$5:$A$11,0)),"") -> 46303 | R25: =IFERROR(INDEX(Refs_Embarques!$I$5:$I$11,MATCH(N25,Refs_Embarques!$A$5:$A$11,0)),"") -> 46310
A26: SZ-03 | B26: 2026-07-15 | C26: 2026-09-15 | D26: 528 | E26: T-Care | F26: TCRANEBL | G26: Afeitadora Rasuradora Corporal Electrica NeoBlade 3.1 T-Care | H26: 200 | I26: 0.391 | J26: 2100 | L26: LATE | M26: 200 | N26: SZ-01(623) | O26: =IFERROR(INDEX(Refs_Embarques!$F$5:$F$11,MATCH(N26,Refs_Embarques!$A$5:$A$11,0)),"") -> 46218 | P26: =IFERROR(INDEX(Refs_Embarques!$G$5:$G$11,MATCH(N26,Refs_Embarques!$A$5:$A$11,0)),"") -> 46225 | Q26: =IFERROR(INDEX(Refs_Embarques!$H$5:$H$11,MATCH(N26,Refs_Embarques!$A$5:$A$11,0)),"") -> 46277 | R26: =IFERROR(INDEX(Refs_Embarques!$I$5:$I$11,MATCH(N26,Refs_Embarques!$A$5:$A$11,0)),"") -> 46284
A27: SZ-03 | B27: 2026-07-15 | C27: 2026-09-15 | D27: 518 | E27: Simplit | F27: SIMJULZSIE-30 | G27: Juego Loza Cerámica 30 pcs Siena 6 personas Simplit | H27: 900 | I27: 45.524 | J27: 14220 | L27: LATE | M27: 900 | N27: SZ-01(623) | O27: =IFERROR(INDEX(Refs_Embarques!$F$5:$F$11,MATCH(N27,Refs_Embarques!$A$5:$A$11,0)),"") -> 46218 | P27: =IFERROR(INDEX(Refs_Embarques!$G$5:$G$11,MATCH(N27,Refs_Embarques!$A$5:$A$11,0)),"") -> 46225 | Q27: =IFERROR(INDEX(Refs_Embarques!$H$5:$H$11,MATCH(N27,Refs_Embarques!$A$5:$A$11,0)),"") -> 46277 | R27: =IFERROR(INDEX(Refs_Embarques!$I$5:$I$11,MATCH(N27,Refs_Embarques!$A$5:$A$11,0)),"") -> 46284
A28: SZ-03 | B28: 2026-07-15 | C28: 2026-09-15 | D28: 518 | E28: Simplit | F28: SIMJULZBRU-30 | G28: Juego de Loza 30 pcs Cerámica Bruselas 6 personas Simplit | H28: 300 | I28: 18.895 | J28: 6141 | L28: LATE | M28: 300 | N28: SZ-01(623) | O28: =IFERROR(INDEX(Refs_Embarques!$F$5:$F$11,MATCH(N28,Refs_Embarques!$A$5:$A$11,0)),"") -> 46218 | P28: =IFERROR(INDEX(Refs_Embarques!$G$5:$G$11,MATCH(N28,Refs_Embarques!$A$5:$A$11,0)),"") -> 46225 | Q28: =IFERROR(INDEX(Refs_Embarques!$H$5:$H$11,MATCH(N28,Refs_Embarques!$A$5:$A$11,0)),"") -> 46277 | R28: =IFERROR(INDEX(Refs_Embarques!$I$5:$I$11,MATCH(N28,Refs_Embarques!$A$5:$A$11,0)),"") -> 46284
A29: SZ-04 | B29: 2026-07-31 | C29: 2026-10-01 | D29: 518 | E29: Simplit | F29: SIMJULZOPO-30 | G29: Juego de Loza 30 pcs Cerámica Oporto Simplit | H29: 400 | I29: 23.169 | J29: 7840 | L29: LATE | M29: 400 | N29: SZ-02(623) | O29: =IFERROR(INDEX(Refs_Embarques!$F$5:$F$11,MATCH(N29,Refs_Embarques!$A$5:$A$11,0)),"") -> 46244 | P29: =IFERROR(INDEX(Refs_Embarques!$G$5:$G$11,MATCH(N29,Refs_Embarques!$A$5:$A$11,0)),"") -> 46251 | Q29: =IFERROR(INDEX(Refs_Embarques!$H$5:$H$11,MATCH(N29,Refs_Embarques!$A$5:$A$11,0)),"") -> 46303 | R29: =IFERROR(INDEX(Refs_Embarques!$I$5:$I$11,MATCH(N29,Refs_Embarques!$A$5:$A$11,0)),"") -> 46310
A30: SZ-04 | B30: 2026-07-31 | C30: 2026-10-01 | D30: 518 | E30: Simplit | F30: SIMPLSIE-4 | G30: Set 4 Platos Fondo Cerámica 26,7cm Siena Simplit | H30: 200 | I30: 1.567 | J30: 690 | L30: LATE | M30: 204 | N30: SZ-02(623) | O30: =IFERROR(INDEX(Refs_Embarques!$F$5:$F$11,MATCH(N30,Refs_Embarques!$A$5:$A$11,0)),"") -> 46244 | P30: =IFERROR(INDEX(Refs_Embarques!$G$5:$G$11,MATCH(N30,Refs_Embarques!$A$5:$A$11,0)),"") -> 46251 | Q30: =IFERROR(INDEX(Refs_Embarques!$H$5:$H$11,MATCH(N30,Refs_Embarques!$A$5:$A$11,0)),"") -> 46303 | R30: =IFERROR(INDEX(Refs_Embarques!$I$5:$I$11,MATCH(N30,Refs_Embarques!$A$5:$A$11,0)),"") -> 46310
A31: SZ-04 | B31: 2026-07-31 | C31: 2026-10-01 | D31: 518 | E31: Lhotse | F31: LHMOBROBK | G31: Mochila Viaje Impermeable Porta Notebook 17.3" 40L Broadpeak Black Lhotse | H31: 300 | I31: 3.492 | J31: 6000 | L31: LATE | M31: 300 | N31: SZ-04,40HQ | O31: =IFERROR(INDEX(Refs_Embarques!$F$5:$F$11,MATCH(N31,Refs_Embarques!$A$5:$A$11,0)),"") -> 46204 | P31: =IFERROR(INDEX(Refs_Embarques!$G$5:$G$11,MATCH(N31,Refs_Embarques!$A$5:$A$11,0)),"") -> 46211 | Q31: =IFERROR(INDEX(Refs_Embarques!$H$5:$H$11,MATCH(N31,Refs_Embarques!$A$5:$A$11,0)),"") -> 46263 | R31: =IFERROR(INDEX(Refs_Embarques!$I$5:$I$11,MATCH(N31,Refs_Embarques!$A$5:$A$11,0)),"") -> 46270
A32: SZ-04 | B32: 2026-07-31 | C32: 2026-10-01 | D32: 518 | E32: Simplit | F32: SIMCUHOL-5 | G32: Set Cuchillos Holz 5 pcs Acero Inoxidable + Taco Simplit | H32: 100 | I32: 1.033 | J32: 2435 | L32: LATE | M32: 100 | N32: SZ-02(623) | O32: =IFERROR(INDEX(Refs_Embarques!$F$5:$F$11,MATCH(N32,Refs_Embarques!$A$5:$A$11,0)),"") -> 46244 | P32: =IFERROR(INDEX(Refs_Embarques!$G$5:$G$11,MATCH(N32,Refs_Embarques!$A$5:$A$11,0)),"") -> 46251 | Q32: =IFERROR(INDEX(Refs_Embarques!$H$5:$H$11,MATCH(N32,Refs_Embarques!$A$5:$A$11,0)),"") -> 46303 | R32: =IFERROR(INDEX(Refs_Embarques!$I$5:$I$11,MATCH(N32,Refs_Embarques!$A$5:$A$11,0)),"") -> 46310
A33: SZ-04 | B33: 2026-07-31 | C33: 2026-10-01 | D33: 518 | E33: Simplit | F33: SIMCUMAR-BK | G33: Set Cuchillos 5 pcs Paris Acero Inoxidable Simplit | H33: 500 | I33: 0.627 | J33: 1385 | L33: LATE | M33: 504 | N33: SZ-02(623) | O33: =IFERROR(INDEX(Refs_Embarques!$F$5:$F$11,MATCH(N33,Refs_Embarques!$A$5:$A$11,0)),"") -> 46244 | P33: =IFERROR(INDEX(Refs_Embarques!$G$5:$G$11,MATCH(N33,Refs_Embarques!$A$5:$A$11,0)),"") -> 46251 | Q33: =IFERROR(INDEX(Refs_Embarques!$H$5:$H$11,MATCH(N33,Refs_Embarques!$A$5:$A$11,0)),"") -> 46303 | R33: =IFERROR(INDEX(Refs_Embarques!$I$5:$I$11,MATCH(N33,Refs_Embarques!$A$5:$A$11,0)),"") -> 46310
A34: SZ-03-08,40HQ | C34: 46274 | D34: MISSING→OHNSO | E34: Levo | F34: 1659990828178 | G34: Control Joystick Inalámbrico doble Shock P4 Negro LEVO | H34: 50 | I34: 0.079 | J34: 397.5 | M34: 50 | N34: SZ-03-08,40HQ | O34: 46208 | P34: 46215 | Q34: 46267 | R34: 46274
A35: SZ-03-08,40HQ | C35: 46274 | D35: MISSING→OHNSO | E35: Levo | F35: 66436804863605 | G35: Control Joystick Inalámbrico doble Shock P4 Rojo LEVO | H35: 50 | I35: 0.079 | J35: 400 | M35: 50 | N35: SZ-03-08,40HQ | O35: 46208 | P35: 46215 | Q35: 46267 | R35: 46274
A36: SZ-01(623) | C36: 46284 | D36: MISSING→OHNSO | E36: Lhotse | F36: LHMOBI001-BK | G36: Mochila Outdoor con Bolsa de Agua HydroRoad Black Lhotse | H36: 300 | I36: 1.181 | J36: 2850 | M36: 300 | N36: SZ-01(623) | O36: 46218 | P36: 46225 | Q36: 46277 | R36: 46284
A37: SZ-02(623) | C37: 46310 | D37: MISSING→OHNSO | E37: Simplit | F37: SMVABOR4 | G37: Set 4 Vasos Vidrio Borosilicato 550 ml Simplit | H37: 100 | I37: 0.696 | J37: 220 | M37: 100 | N37: SZ-02(623) | O37: 46244 | P37: 46251 | Q37: 46303 | R37: 46310
A38: SZ-02(623) | C38: 46310 | D38: MISSING→OHNSO | E38: Simplit | F38: SIMDESSOM | G38: Descorchador Abridor Vino Sommelier Simplit | H38: 100 | I38: 0.013 | J38: 232 | M38: 100 | N38: SZ-02(623) | O38: 46244 | P38: 46251 | Q38: 46303 | R38: 46310
A39: SZ-04,40HQ | C39: 46270 | D39: MISSING→OHNSO | E39: Simplit | F39: 1628018206370 | G39: Juego De 4 Cachos Eco Cuero Negro Simplit | H39: 100 | I39: 0.266 | J39: 360 | M39: 100 | N39: SZ-04,40HQ | O39: 46204 | P39: 46211 | Q39: 46263 | R39: 46270
A40: SZ-02(623) | C40: 46310 | D40: MISSING→OHNSO | E40: Xroad | F40: XRCARRTRACT-CL | G40: Carro de Transporte con Techo 150 KG Negro Xroad | H40: 200 | I40: 17.783 | J40: 4700 | M40: 200 | N40: SZ-02(623) | O40: 46244 | P40: 46251 | Q40: 46303 | R40: 46310
...

Sheet Detail_NB
A1: Container | B1: CRD | C1: ETA | D1: Order No | E1: Brand | F1: SKU | G1: Description | H1: Units | I1: CBM | J1: USD Value | K1: Need to pay? | L1: Late? | M1: Cantidad cargada | N1: Embarque (Steven) | O1: CRD | P1: ETD | Q1: ETA Puerto | R1: ETA Bodega
A2: NB-01 | B2: 2026-07-20 | C2: 2026-09-10 | D2: 528 | E2: T-Care | F2: TCMULTSTY5N1 | G2: Secador de pelo Multistyler T-Care 5 en 1 | H2: 2000 | I2: 26.182 | J2: 48000 | L2: LATE | M2: 2004 | N2: NB-01 | O2: =IFERROR(INDEX(Refs_Embarques!$F$5:$F$11,MATCH(N2,Refs_Embarques!$A$5:$A$11,0)),"") -> 46223 | P2: =IFERROR(INDEX(Refs_Embarques!$G$5:$G$11,MATCH(N2,Refs_Embarques!$A$5:$A$11,0)),"") -> 46230 | Q2: =IFERROR(INDEX(Refs_Embarques!$H$5:$H$11,MATCH(N2,Refs_Embarques!$A$5:$A$11,0)),"") -> 46275 | R2: =IFERROR(INDEX(Refs_Embarques!$I$5:$I$11,MATCH(N2,Refs_Embarques!$A$5:$A$11,0)),"") -> 46282
A3: NB-01 | B3: 2026-07-20 | C3: 2026-09-10 | D3: MANUAL | E3: T-Care | F3: TCMULTSTY5N1-BG | G3: Secador de pelo Multistyler 5 en 1 AeroFlow Beige | H3: 1000 | I3: 13.092 | J3: 24000 | L3: LATE | M3: 1002 | N3: NB-01 | O3: =IFERROR(INDEX(Refs_Embarques!$F$5:$F$11,MATCH(N3,Refs_Embarques!$A$5:$A$11,0)),"") -> 46223 | P3: =IFERROR(INDEX(Refs_Embarques!$G$5:$G$11,MATCH(N3,Refs_Embarques!$A$5:$A$11,0)),"") -> 46230 | Q3: =IFERROR(INDEX(Refs_Embarques!$H$5:$H$11,MATCH(N3,Refs_Embarques!$A$5:$A$11,0)),"") -> 46275 | R3: =IFERROR(INDEX(Refs_Embarques!$I$5:$I$11,MATCH(N3,Refs_Embarques!$A$5:$A$11,0)),"") -> 46282
A4: NB-02 | C4: 46308 | D4: MISSING→OHNSO | E4: Bandú | F4: BDCOCPQMD | G4: Cocina de Juguete Infantil Niños Madera Rosada con Acc Bandú | H4: 80 | I4: 2.843 | J4: 1918.4 | M4: 80 | N4: NB-02 | O4: 46249 | P4: 46256 | Q4: 46301 | R4: 46308
A5: NB-02 | C5: 46308 | D5: MISSING→OHNSO | E5: Bandú | F5: BDSETDOC | G5: Set Juego de Roles Doctor Niños Madera 12 pcs Bandú | H5: 80 | I5: 0.302 | J5: 416 | M5: 80 | N5: NB-02 | O5: 46249 | P5: 46256 | Q5: 46301 | R5: 46308
A6: NB-02 | C6: 46308 | D6: MISSING→OHNSO | E6: Bandú | F6: BDCOCMEDI | G6: Cocina de Juguete Infantil Niños Madera 11 Accesorios Bandú | H6: 50 | I6: 2.155 | J6: 1447.5 | M6: 50 | N6: NB-02 | O6: 46249 | P6: 46256 | Q6: 46301 | R6: 46308
A7: NB-02 | C7: 46308 | D7: MISSING→OHNSO | E7: Bandú | F7: BDCOCGRND | G7: Cocina de Juguete Infantil Niños Madera Accesorios Bandú | H7: 30 | I7: 1.538 | J7: 960.3 | M7: 30 | N7: NB-02 | O7: 46249 | P7: 46256 | Q7: 46301 | R7: 46308
A8: NB-02 | C8: 46308 | D8: MISSING→OHNSO | E8: Bandú | F8: BDPZMG2E1 | G8: Pizarra Madera Infantil Magnética 2 en 1 Didáctica Bandú | H8: 30 | I8: 0.33 | J8: 420 | M8: 30 | N8: NB-02 | O8: 46249 | P8: 46256 | Q8: 46301 | R8: 46308
A9: NB-02 | C9: 46308 | D9: MISSING→OHNSO | E9: Bandú | F9: BDTOCMD-WH | G9: Tocador Infantil Para Niñas Espejo Maquillaje Madera Bandú | H9: 30 | I9: 1.847 | J9: 884.7 | M9: 30 | N9: NB-02 | O9: 46249 | P9: 46256 | Q9: 46301 | R9: 46308
A10: NB-02 | C10: 46308 | D10: MISSING→OHNSO | E10: Bandú | F10: BDJUETRE | G10: Pista de Autos y Tren de Madera Juego Didactico 70pcs Bandú | H10: 30 | I10: 0.359 | J10: 470.1 | M10: 30 | N10: NB-02 | O10: 46249 | P10: 46256 | Q10: 46301 | R10: 46308
A11: NB-02 | C11: 46308 | D11: MISSING→OHNSO | E11: Bandú | F11: BDCASMUÑEC-WD | G11: Casa de Muñecas de Madera Juguete Infantil Bandú | H11: 15 | I11: 0.472 | J11: 324.9 | M11: 15 | N11: NB-02 | O11: 46249 | P11: 46256 | Q11: 46301 | R11: 46308
A12: NB-02 | C12: 46308 | D12: MISSING→OHNSO | E12: Bandú | F12: BDMESHERRA | G12: Juego de Construcción Herramientas Madera para Niños Bandú | H12: 15 | I12: 0.317 | J12: 270 | M12: 15 | N12: NB-02 | O12: 46249 | P12: 46256 | Q12: 46301 | R12: 46308
A13: NB-02 | C13: 46308 | D13: MISSING→OHNSO | E13: Bandú | F13: BDGMNMVBB | G13: Gimnasio Móvil de Madera Bebé Infantil Bandú | H13: 15 | I13: 0.104 | J13: 165 | M13: 15 | N13: NB-02 | O13: 46249 | P13: 46256 | Q13: 46301 | R13: 46308
A14: IMP OP 351-26 40HQ | C14: 46279 | D14: MISSING→OHNSO | E14: Bandú | F14: BDGIMPIK | G14: Gimnasio Infantil Juego Pikler Parque 8 en 1 Bandú | H14: 5 | I14: 0.372 | J14: 400 | M14: 5 | N14: IMP OP 351-26 40HQ | O14: 46213 | P14: 46220 | Q14: 46272 | R14: 46279
A15: NB-01 | C15: 46282 | D15: MISSING→OHNSO | E15: Lhotse | F15: LHSHNUCO-NY | G15: Shaker Vaso Proteina Acero Inox NutriCore 500ml Blue Lhotse | H15: 500 | M15: 500 | N15: NB-01 | O15: 46223 | P15: 46230 | Q15: 46275 | R15: 46282
A16: NB-01 | C16: 46282 | D16: MISSING→OHNSO | E16: Lhotse | F16: LHSHNUCO-BG | G16: Shaker Vaso Proteina Acero Inox NutriCore 500ml Beige Lhotse | H16: 300 | M16: 300 | N16: NB-01 | O16: 46223 | P16: 46230 | Q16: 46275 | R16: 46282
A17: NB-02 | C17: 46308 | D17: MISSING→OHNSO | E17: Simplit | F17: 67327712330533 | G17: Set de 7 Contenedores Herméticos Plástico Negro Simplit | H17: 500 | I17: 7.997 | J17: 3025 | M17: 500 | N17: NB-02 | O17: 46249 | P17: 46256 | Q17: 46301 | R17: 46308
A18: IMP OP 351-26 40HQ | C18: 46279 | D18: MISSING→OHNSO | E18: Simplit | F18: SMBATSAV9-CR | G18: Batería de Cocina Antiadherente Savannah 9 Piezas | H18: 300 | I18: 13.541 | J18: 9690 | M18: 300 | N18: IMP OP 351-26 40HQ | O18: 46213 | P18: 46220 | Q18: 46272 | R18: 46279
A19: IMP OP 351-26 40HQ | C19: 46279 | D19: MISSING→OHNSO | E19: Simplit | F19: 1660858702400 | G19: Set 2 Molinillos de Sal y Pimienta Vidrio Simplit | H19: 100 | I19: 0.403 | J19: 330 | M19: 100 | N19: IMP OP 351-26 40HQ | O19: 46213 | P19: 46220 | Q19: 46272 | R19: 46279
A20: IMP OP 351-26 40HQ | C20: 46279 | D20: MISSING→OHNSO | E20: Simplit | F20: SIMDECROU | G20: Decantador Aireador Vino Rouge 1500ml | H20: 100 | I20: 1.424 | J20: 526 | M20: 100 | N20: IMP OP 351-26 40HQ | O20: 46213 | P20: 46220 | Q20: 46272 | R20: 46279
A21: NB-02 | C21: 46308 | D21: MISSING→OHNSO | E21: Xroad | F21: XRCOOLPORT-GR | G21: Cooler Eléctrico Portátil 30L 12V Gris Xroad | H21: 250 | I21: 17.251 | J21: 6250 | M21: 250 | N21: NB-02 | O21: 46249 | P21: 46256 | Q21: 46301 | R21: 46308
A22: IMP OP 350-26 40HQ | C22: 46269 | D22: MISSING→OHNSO | E22: Xroad | F22: XRCOOLPORT40-GR | G22: Cooler Eléctrico Portátil 40L 12V Gris Xroad | H22: 200 | J22: 6492 | M22: 200 | N22: IMP OP 350-26 40HQ | O22: 46203 | P22: 46210 | Q22: 46262 | R22: 46269
A23: IMP OP 351-26 40HQ | C23: 46279 | D23: MISSING→OHNSO | E23: Xroad | F23: XRCOBMOT-BS | G23: Carpa Funda Cubre Moto Impermeable Premium con Felpa Xroad | H23: 120 | I23: 0.378 | J23: 552 | M23: 120 | N23: IMP OP 351-26 40HQ | O23: 46213 | P23: 46220 | Q23: 46272 | R23: 46279
A24: IMP OP 351-26 40HQ | C24: 46279 | D24: MISSING→OHNSO | E24: Xroad | F24: XRPISUNIS3-BK | G24: Alfombra Piso de Goma para auto Universal 3 piezas Xroad | H24: 100 | I24: 0.79 | J24: 300 | M24: 100 | N24: IMP OP 351-26 40HQ | O24: 46213 | P24: 46220 | Q24: 46272 | R24: 46279
A25: IMP OP 350-26 40HQ | C25: 46269 | D25: MISSING→OHNSO | E25: Xroad | F25: XRCOOLPORTF40-GR | G25: Cooler Freezer Eléctrico Portátil 40L 12V Gris Xroad | H25: 100 | J25: 7700 | M25: 100 | N25: IMP OP 350-26 40HQ | O25: 46203 | P25: 46210 | Q25: 46262 | R25: 46269
A26: NB-02 | C26: 46308 | D26: MISSING→OHNSO | E26: Xroad | F26: 1650302269777 | G26: Toldo Camping Lateral Para Auto Techo Xroad | H26: 30 | I26: 0.961 | J26: 1950 | M26: 30 | N26: NB-02 | O26: 46249 | P26: 46256 | Q26: 46301 | R26: 46308
A27: NB-01 | C27: 46282 | D27: MISSING→OHNSO | E27: Lhotse | F27: LHSHNUCO-BK | G27: Shaker Vaso Proteina Acero Inox NutriCore Negro | H27: 200 | I27: 0.565 | J27: 796 | M27: 200 | N27: NB-01 | O27: 46223 | P27: 46230 | Q27: 46275 | R27: 46282

Sheet Late_Arrivals
A1: Brand | B1: SKU | C1: Description | D1: Port | E1: Units | F1: CRD | G1: ETA | H1: Days past Aug 31 | I1: Cantidad cargada | J1: Embarque (Steven) | K1: CRD | L1: ETD | M1: ETA Puerto | N1: ETA Bodega
A2: Simplit | B2: 1630369674271 | C2: Cafetera Prensa Francesa Negra 600 ml Simplit | D2: SZ | E2: 150 | F2: 2026-07-05 | G2: 2026-09-05 | H2: +5 | I2: 150 | J2: SZ-01(623) | K2: =IFERROR(INDEX(Refs_Embarques!$F$5:$F$11,MATCH(J2,Refs_Embarques!$A$5:$A$11,0)),"") -> 46218 | L2: =IFERROR(INDEX(Refs_Embarques!$G$5:$G$11,MATCH(J2,Refs_Embarques!$A$5:$A$11,0)),"") -> 46225 | M2: =IFERROR(INDEX(Refs_Embarques!$H$5:$H$11,MATCH(J2,Refs_Embarques!$A$5:$A$11,0)),"") -> 46277 | N2: =IFERROR(INDEX(Refs_Embarques!$I$5:$I$11,MATCH(J2,Refs_Embarques!$A$5:$A$11,0)),"") -> 46284
A3: Simplit | B3: SIMOREXBAS-WD | C3: Organizador Cubiertos Expandible Madera Acasia Basel Simplit | D3: SZ | E3: 300 | F3: 2026-07-05 | G3: 2026-09-05 | H3: +5 | I3: 300 | J3: SZ-02(623) | K3: =IFERROR(INDEX(Refs_Embarques!$F$5:$F$11,MATCH(J3,Refs_Embarques!$A$5:$A$11,0)),"") -> 46244 | L3: =IFERROR(INDEX(Refs_Embarques!$G$5:$G$11,MATCH(J3,Refs_Embarques!$A$5:$A$11,0)),"") -> 46251 | M3: =IFERROR(INDEX(Refs_Embarques!$H$5:$H$11,MATCH(J3,Refs_Embarques!$A$5:$A$11,0)),"") -> 46303 | N3: =IFERROR(INDEX(Refs_Embarques!$I$5:$I$11,MATCH(J3,Refs_Embarques!$A$5:$A$11,0)),"") -> 46310
A4: T-Care | B4: TCRANEBL | C4: Afeitadora Rasuradora Corporal Electrica NeoBlade 3.1 T-Care | D4: SZ | E4: 200 | F4: 2026-07-10 | G4: 2026-09-10 | H4: +10 | I4: 200 | J4: SZ-01(623) | K4: =IFERROR(INDEX(Refs_Embarques!$F$5:$F$11,MATCH(J4,Refs_Embarques!$A$5:$A$11,0)),"") -> 46218 | L4: =IFERROR(INDEX(Refs_Embarques!$G$5:$G$11,MATCH(J4,Refs_Embarques!$A$5:$A$11,0)),"") -> 46225 | M4: =IFERROR(INDEX(Refs_Embarques!$H$5:$H$11,MATCH(J4,Refs_Embarques!$A$5:$A$11,0)),"") -> 46277 | N4: =IFERROR(INDEX(Refs_Embarques!$I$5:$I$11,MATCH(J4,Refs_Embarques!$A$5:$A$11,0)),"") -> 46284
A5: T-Care | B5: TCMULTSTY5N1 | C5: Secador de pelo Multistyler T-Care 5 en 1 | D5: NB | E5: 2000 | F5: 2026-07-20 | G5: 2026-09-10 | H5: +10 | I5: 2004 | J5: NB-01 | K5: =IFERROR(INDEX(Refs_Embarques!$F$5:$F$11,MATCH(J5,Refs_Embarques!$A$5:$A$11,0)),"") -> 46223 | L5: =IFERROR(INDEX(Refs_Embarques!$G$5:$G$11,MATCH(J5,Refs_Embarques!$A$5:$A$11,0)),"") -> 46230 | M5: =IFERROR(INDEX(Refs_Embarques!$H$5:$H$11,MATCH(J5,Refs_Embarques!$A$5:$A$11,0)),"") -> 46275 | N5: =IFERROR(INDEX(Refs_Embarques!$I$5:$I$11,MATCH(J5,Refs_Embarques!$A$5:$A$11,0)),"") -> 46282
A6: T-Care | B6: TCMULTSTY5N1-BG | C6: Secador de pelo Multistyler 5 en 1 AeroFlow Beige | D6: NB | E6: 1000 | F6: 2026-07-20 | G6: 2026-09-10 | H6: +10 | I6: 2004 | J6: NB-01 | K6: =IFERROR(INDEX(Refs_Embarques!$F$5:$F$11,MATCH(J6,Refs_Embarques!$A$5:$A$11,0)),"") -> 46223 | L6: =IFERROR(INDEX(Refs_Embarques!$G$5:$G$11,MATCH(J6,Refs_Embarques!$A$5:$A$11,0)),"") -> 46230 | M6: =IFERROR(INDEX(Refs_Embarques!$H$5:$H$11,MATCH(J6,Refs_Embarques!$A$5:$A$11,0)),"") -> 46275 | N6: =IFERROR(INDEX(Refs_Embarques!$I$5:$I$11,MATCH(J6,Refs_Embarques!$A$5:$A$11,0)),"") -> 46282
A7: Simplit | B7: SIMJULZSIE-30 | C7: Juego Loza Cerámica 30 pcs Siena 6 personas Simplit | D7: SZ | E7: 900 | F7: 2026-07-15 | G7: 2026-09-15 | H7: +15 | I7: 900 | J7: SZ-01(623) | K7: =IFERROR(INDEX(Refs_Embarques!$F$5:$F$11,MATCH(J7,Refs_Embarques!$A$5:$A$11,0)),"") -> 46218 | L7: =IFERROR(INDEX(Refs_Embarques!$G$5:$G$11,MATCH(J7,Refs_Embarques!$A$5:$A$11,0)),"") -> 46225 | M7: =IFERROR(INDEX(Refs_Embarques!$H$5:$H$11,MATCH(J7,Refs_Embarques!$A$5:$A$11,0)),"") -> 46277 | N7: =IFERROR(INDEX(Refs_Embarques!$I$5:$I$11,MATCH(J7,Refs_Embarques!$A$5:$A$11,0)),"") -> 46284
A8: Simplit | B8: SIMJULZBRU-30 | C8: Juego de Loza 30 pcs Cerámica Bruselas 6 personas Simplit | D8: SZ | E8: 300 | F8: 2026-07-15 | G8: 2026-09-15 | H8: +15 | I8: 300 | J8: SZ-01(623) | K8: =IFERROR(INDEX(Refs_Embarques!$F$5:$F$11,MATCH(J8,Refs_Embarques!$A$5:$A$11,0)),"") -> 46218 | L8: =IFERROR(INDEX(Refs_Embarques!$G$5:$G$11,MATCH(J8,Refs_Embarques!$A$5:$A$11,0)),"") -> 46225 | M8: =IFERROR(INDEX(Refs_Embarques!$H$5:$H$11,MATCH(J8,Refs_Embarques!$A$5:$A$11,0)),"") -> 46277 | N8: =IFERROR(INDEX(Refs_Embarques!$I$5:$I$11,MATCH(J8,Refs_Embarques!$A$5:$A$11,0)),"") -> 46284
A9: Simplit | B9: SIMJULZOPO-30 | C9: Juego de Loza 30 pcs Cerámica Oporto Simplit | D9: SZ | E9: 400 | F9: 2026-07-15 | G9: 2026-09-15 | H9: +15 | I9: 400 | J9: SZ-02(623) | K9: =IFERROR(INDEX(Refs_Embarques!$F$5:$F$11,MATCH(J9,Refs_Embarques!$A$5:$A$11,0)),"") -> 46244 | L9: =IFERROR(INDEX(Refs_Embarques!$G$5:$G$11,MATCH(J9,Refs_Embarques!$A$5:$A$11,0)),"") -> 46251 | M9: =IFERROR(INDEX(Refs_Embarques!$H$5:$H$11,MATCH(J9,Refs_Embarques!$A$5:$A$11,0)),"") -> 46303 | N9: =IFERROR(INDEX(Refs_Embarques!$I$5:$I$11,MATCH(J9,Refs_Embarques!$A$5:$A$11,0)),"") -> 46310
A10: Simplit | B10: SIMPLSIE-4 | C10: Set 4 Platos Fondo Cerámica 26,7cm Siena Simplit | D10: SZ | E10: 200 | F10: 2026-07-15 | G10: 2026-09-15 | H10: +15 | I10: 204 | J10: SZ-02(623) | K10: =IFERROR(INDEX(Refs_Embarques!$F$5:$F$11,MATCH(J10,Refs_Embarques!$A$5:$A$11,0)),"") -> 46244 | L10: =IFERROR(INDEX(Refs_Embarques!$G$5:$G$11,MATCH(J10,Refs_Embarques!$A$5:$A$11,0)),"") -> 46251 | M10: =IFERROR(INDEX(Refs_Embarques!$H$5:$H$11,MATCH(J10,Refs_Embarques!$A$5:$A$11,0)),"") -> 46303 | N10: =IFERROR(INDEX(Refs_Embarques!$I$5:$I$11,MATCH(J10,Refs_Embarques!$A$5:$A$11,0)),"") -> 46310
A11: Lhotse | B11: LHMOBROBK | C11: Mochila Viaje Impermeable Porta Notebook 17.3" 40L Broadpeak Black Lhotse | D11: SZ | E11: 300 | F11: 2026-07-20 | G11: 2026-09-20 | H11: +20 | I11: 300 | J11: SZ-04,40HQ | K11: =IFERROR(INDEX(Refs_Embarques!$F$5:$F$11,MATCH(J11,Refs_Embarques!$A$5:$A$11,0)),"") -> 46204 | L11: =IFERROR(INDEX(Refs_Embarques!$G$5:$G$11,MATCH(J11,Refs_Embarques!$A$5:$A$11,0)),"") -> 46211 | M11: =IFERROR(INDEX(Refs_Embarques!$H$5:$H$11,MATCH(J11,Refs_Embarques!$A$5:$A$11,0)),"") -> 46263 | N11: =IFERROR(INDEX(Refs_Embarques!$I$5:$I$11,MATCH(J11,Refs_Embarques!$A$5:$A$11,0)),"") -> 46270
A12: Simplit | B12: SIMCUHOL-5 | C12: Set Cuchillos Holz 5 pcs Acero Inoxidable + Taco Simplit | D12: SZ | E12: 100 | F12: 2026-07-24 | G12: 2026-09-24 | H12: +24 | I12: 100 | J12: SZ-02(623) | K12: =IFERROR(INDEX(Refs_Embarques!$F$5:$F$11,MATCH(J12,Refs_Embarques!$A$5:$A$11,0)),"") -> 46244 | L12: =IFERROR(INDEX(Refs_Embarques!$G$5:$G$11,MATCH(J12,Refs_Embarques!$A$5:$A$11,0)),"") -> 46251 | M12: =IFERROR(INDEX(Refs_Embarques!$H$5:$H$11,MATCH(J12,Refs_Embarques!$A$5:$A$11,0)),"") -> 46303 | N12: =IFERROR(INDEX(Refs_Embarques!$I$5:$I$11,MATCH(J12,Refs_Embarques!$A$5:$A$11,0)),"") -> 46310
A13: Simplit | B13: SIMCUMAR-BK | C13: Set Cuchillos 5 pcs Paris Acero Inoxidable Simplit | D13: SZ | E13: 500 | F13: 2026-07-31 | G13: 2026-10-01 | H13: +31 | I13: 504 | J13: SZ-02(623) | K13: =IFERROR(INDEX(Refs_Embarques!$F$5:$F$11,MATCH(J13,Refs_Embarques!$A$5:$A$11,0)),"") -> 46244 | L13: =IFERROR(INDEX(Refs_Embarques!$G$5:$G$11,MATCH(J13,Refs_Embarques!$A$5:$A$11,0)),"") -> 46251 | M13: =IFERROR(INDEX(Refs_Embarques!$H$5:$H$11,MATCH(J13,Refs_Embarques!$A$5:$A$11,0)),"") -> 46303 | N13: =IFERROR(INDEX(Refs_Embarques!$I$5:$I$11,MATCH(J13,Refs_Embarques!$A$5:$A$11,0)),"") -> 46310

Sheet Pend_Confirmation
A1: Brand | B1: SKU | C1: Description | D1: Units Pend. | E1: Note | F1: Cantidad cargada | G1: Embarque (Steven) | H1: CRD | I1: ETD | J1: ETA Puerto | K1: ETA Bodega
A2: Simplit | B2: SMBATOXBG | C2: Batería de Cocina Antiadherente Oxford Granito 15 pcs Beige | D2: 600 | E2: Supplier status: new model / pre-sample / to be confirmed | F2: 600 | G2: Rest items | H2: =IFERROR(INDEX(Refs_Embarques!$F$5:$F$11,MATCH(G2,Refs_Embarques!$A$5:$A$11,0)),"") -> 46248 | I2: =IFERROR(INDEX(Refs_Embarques!$G$5:$G$11,MATCH(G2,Refs_Embarques!$A$5:$A$11,0)),"") -> 46255 | J2: =IFERROR(INDEX(Refs_Embarques!$H$5:$H$11,MATCH(G2,Refs_Embarques!$A$5:$A$11,0)),"") -> 46307 | K2: =IFERROR(INDEX(Refs_Embarques!$I$5:$I$11,MATCH(G2,Refs_Embarques!$A$5:$A$11,0)),"") -> 46314

Sheet Missing
A1: Brand | B1: SKU | C1: Description | D1: Missing Units | E1: Comments | F1: Cantidad cargada | G1: Embarque (Steven) | H1: CRD | I1: ETD | J1: ETA Puerto | K1: ETA Bodega
A2: Lhotse | B2: LHSWVIBBK | C2: Reloj Smartwatch Lhotse Vibe 05 GPS Black 45mm | D2: 100 | E2: CHECK STEVEN
A3: Simplit | B3: SIMJULZSIEBL-30 | C3: Juego Loza Cerámica 30 pcs Siena Blanca 6 personas Simplit | D3: 500 | E3: CRD 14-08
A4: Simplit | B4: SIMBACOHA-55 | C4: Basurero Cocina Handy 55lts Táctil Acero Inox Simplit | D4: 150 | E4: ETA AUGUST
A5: Simplit | B5: SIMPLAMA-4 | C5: Set 4 Platos Fondo Cerámica 27,4 cm Amalfi Simplit | D5: 150 | E5: CANCELLED
A6: Simplit | B6: 1660858025311 | C6: Bowl Cortador Rallador de Verduras Multifuncional Simplit | D6: 120 | E6: ETA AUGUST
A7: UMA | B7: MTVTUMBPR590 | C7: Vaso Termico Tumbler Mug Barbie Print 590ml Acero Inox UMA | D7: 500 | E7: BATCH 617
A8: Xroad | B8: XRCOOLPOR50-BK | C8: Cooler Portátil 50L con Ruedas Negro Xroad | D8: 200 | E8: BATCH 617
A9: Xroad | B9: 1656603353038 | C9: Funda Cubre Asiento de Auto Impermeable Mascotas Negra Xroad | D9: 100 | E9: CANCELLED
A10: Xroad | B10: XRTOLLAT270-BG | C10: Toldo Camping Lateral Para Auto Techo 270° Xroad | D10: 10 | E10: BATCH 615

Sheet SKU_Classification
A1: Brand | B1: SKU | C1: Description | D1: Demand | E1: Ship | F1: Pend | G1: Missing | H1: Category
A2: Levo | B2: 67327559384453 | C2: Cámara HD Auto D3 Frontal, Interior y Trasera LEVO | D2: 100 | E2: 100 | F2: 0 | G2: 0 | H2: SHIP
A3: Levo | B3: LVPANTOTPUB-43 | C3: Pantalla Totem Publicitario 43" Touch Android Wifi Usb LEVO | D3: 8 | E3: 8 | F3: 0 | G3: 0 | H3: SHIP
A4: Lhotse | B4: 1571423280815 | C4: Pick-up Pad Lhotse Porta 5 Bicicletas | D4: 100 | E4: 100 | F4: 0 | G4: 0 | H4: SHIP
A5: Lhotse | B5: 1623703861303 | C5: Bolso Deportivo Lhotse Duffel 30 Lts Bag Negro | D5: 300 | E5: 300 | F5: 0 | G5: 0 | H5: SHIP
A6: Lhotse | B6: LHMOBROBK | C6: Mochila Viaje Impermeable Porta Notebook 17.3" 40L Broadpeak Black Lhotse | D6: 300 | E6: 300 | F6: 0 | G6: 0 | H6: SHIP
A7: Lhotse | B7: LHBIGMU-PPN | C7: Vaso Termico Tumbler Acero Inox Antiderrame 1180ml Lilac Lhotse | D7: 100 | E7: 100 | F7: 0 | G7: 0 | H7: SHIP
A8: Lhotse | B8: LHBIGMU-BKN | C8: Vaso Termico Tumbler Acero Inox Antiderrame 1180ml Black Lhotse | D8: 100 | E8: 100 | F8: 0 | G8: 0 | H8: SHIP
A9: Simplit | B9: 1629726091782 | C9: Set 12 Utensilios De Cocina Silicona Calipso Simplit | D9: 300 | E9: 300 | F9: 0 | G9: 0 | H9: SHIP
A10: Simplit | B10: SIMCUPGL-30 | C10: Set de Cuchillería 30 pcs Cubiertos Acero Inoxidable Puglia | D10: 250 | E10: 250 | F10: 0 | G10: 0 | H10: SHIP
A11: Simplit | B11: SIMCUMAR-BK | C11: Set Cuchillos 5 pcs Paris Acero Inoxidable Simplit | D11: 500 | E11: 500 | F11: 0 | G11: 0 | H11: SHIP
A12: Simplit | B12: SIMCUHOL-5 | C12: Set Cuchillos Holz 5 pcs Acero Inoxidable + Taco Simplit | D12: 100 | E12: 100 | F12: 0 | G12: 0 | H12: SHIP
A13: Simplit | B13: 1630369674271 | C13: Cafetera Prensa Francesa Negra 600 ml Simplit | D13: 150 | E13: 150 | F13: 0 | G13: 0 | H13: SHIP
A14: Simplit | B14: 1652825295706 | C14: Cafetera Italiana Negra Granito 12 Tazas Simplit | D14: 200 | E14: 200 | F14: 0 | G14: 0 | H14: SHIP
A15: Simplit | B15: SIMOREXBAS-WD | C15: Organizador Cubiertos Expandible Madera Acasia Basel Simplit | D15: 300 | E15: 300 | F15: 0 | G15: 0 | H15: SHIP
A16: Simplit | B16: 1627418180602 | C16: Especiero Condimentos Giratorio Metálico 16 Frascos Simplit | D16: 200 | E16: 200 | F16: 0 | G16: 0 | H16: SHIP
A17: Simplit | B17: 67933856404072 | C17: Set 6 Vasos Corto Vintage Charlotte 200ml Simplit | D17: 300 | E17: 300 | F17: 0 | G17: 0 | H17: SHIP
A18: Simplit | B18: 67933857637909 | C18: Set 6 Vasos Largo Vintage Charlotte 350ml Simplit | D18: 300 | E18: 300 | F18: 0 | G18: 0 | H18: SHIP
A19: Simplit | B19: 67933863068841 | C19: Set 6 Vaso Copa Cerveza Collins 420ml Simplit | D19: 200 | E19: 200 | F19: 0 | G19: 0 | H19: SHIP
A20: Simplit | B20: SIMVASLARGINE | C20: Set 6 Vasos Largos 460ml Vidrio Ginebra Simplit | D20: 300 | E20: 300 | F20: 0 | G20: 0 | H20: SHIP
A21: Simplit | B21: 1660859171584 | C21: Espumador de Leche 4 en 1 Negro Simplit | D21: 400 | E21: 400 | F21: 0 | G21: 0 | H21: SHIP
A22: Simplit | B22: 68432930518995 | C22: Espumador de Leche 4 en 1 Blanco Simplit | D22: 200 | E22: 200 | F22: 0 | G22: 0 | H22: SHIP
A23: Simplit | B23: SIMJULZSIE-30 | C23: Juego Loza Cerámica 30 pcs Siena 6 personas Simplit | D23: 1200 | E23: 1200 | F23: 0 | G23: 0 | H23: SHIP
A24: Simplit | B24: SIMJULZAMA-24 | C24: Juego Loza Cerámica 24 pcs Amalfi Simplit | D24: 250 | E24: 250 | F24: 0 | G24: 0 | H24: SHIP
A25: Simplit | B25: SIMJULZBRU-30 | C25: Juego de Loza 30 pcs Cerámica Bruselas 6 personas Simplit | D25: 300 | E25: 300 | F25: 0 | G25: 0 | H25: SHIP
A26: Simplit | B26: SIMJULZOPO-30 | C26: Juego de Loza 30 pcs Cerámica Oporto Simplit | D26: 700 | E26: 700 | F26: 0 | G26: 0 | H26: SHIP
A27: Simplit | B27: SIMPLSIE-4 | C27: Set 4 Platos Fondo Cerámica 26,7cm Siena Simplit | D27: 200 | E27: 200 | F27: 0 | G27: 0 | H27: SHIP
A28: Simplit | B28: SIMBOWSIE-4 | C28: Set 4 Bowls Cerámica 8,5cm Siena Simplit | D28: 100 | E28: 100 | F28: 0 | G28: 0 | H28: SHIP
A29: Simplit | B29: SIMTAZSIE-4 | C29: Set 4 Tazas Cerámica 330ml Siena Simplit | D29: 192 | E29: 192 | F29: 0 | G29: 0 | H29: SHIP
A30: T-Care | B30: TCRANEBL | C30: Afeitadora Rasuradora Corporal Electrica NeoBlade 3.1 T-Care | D30: 200 | E30: 200 | F30: 0 | G30: 0 | H30: SHIP
A31: T-Care | B31: TCMULTSTY5N1 | C31: Secador de pelo Multistyler T-Care 5 en 1 | D31: 2000 | E31: 2000 | F31: 0 | G31: 0 | H31: SHIP
A32: T-Care | B32: TCMULTSTY5N1-BG | C32: Secador de pelo Multistyler 5 en 1 AeroFlow Beige | D32: 1000 | E32: 1000 | F32: 0 | G32: 0 | H32: SHIP
A33: Xroad | B33: 1660859424566 | C33: Carpa Funda Cubre Auto Impermeable Premium con Felpa Xroad | D33: 450 | E33: 450 | F33: 0 | G33: 0 | H33: SHIP
A34: Bandú | B34: BDCOCGRND | C34: Cocina de Juguete Infantil Niños Madera Accesorios Bandú | D34: 30 | E34: 0 | F34: 0 | G34: 30 | H34: MISSING
A35: Bandú | B35: BDCOCMEDI | C35: Cocina de Juguete Infantil Niños Madera 11 Accesorios Bandú | D35: 50 | E35: 0 | F35: 0 | G35: 50 | H35: MISSING
A36: Bandú | B36: BDCOCPQMD | C36: Cocina de Juguete Infantil Niños Madera Rosada con Acc Bandú | D36: 80 | E36: 0 | F36: 0 | G36: 80 | H36: MISSING
A37: Bandú | B37: BDSETDOC | C37: Set Juego de Roles Doctor Niños Madera 12 pcs Bandú | D37: 80 | E37: 0 | F37: 0 | G37: 80 | H37: MISSING
A38: Bandú | B38: BDPZMG2E1 | C38: Pizarra Madera Infantil Magnética 2 en 1 Didáctica Bandú | D38: 30 | E38: 0 | F38: 0 | G38: 30 | H38: MISSING
A39: Bandú | B39: BDCASMUÑEC-WD | C39: Casa de Muñecas de Madera Juguete Infantil Bandú | D39: 15 | E39: 0 | F39: 0 | G39: 15 | H39: MISSING
A40: Bandú | B40: BDTOCMD-WH | C40: Tocador Infantil Para Niñas Espejo Maquillaje Madera Bandú | D40: 30 | E40: 0 | F40: 0 | G40: 30 | H40: MISSING
...

Sheet Refs_Embarques
A1: TABLA DE REFERENCIA — Embarques Steven Plan B
A2: Modificar CRD o Tránsito acá → toda la planilla se recalcula.
A4: Embarque | B4: Origen | C4: Tránsito (días) | D4: CRD→ETD (días) | E4: ETA Pto→Bod (días) | F4: CRD | G4: ETD | H4: ETA Puerto | I4: ETA Bodega
A5: SZ-04,40HQ | B5: SZ | C5: 52 | D5: 7 | E5: 7 | F5: 46204 | G5: =F5+D5 -> 46211 | H5: =G5+C5 -> 46263 | I5: =H5+E5 -> 46270
A6: SZ-03-08,40HQ | B6: SZ | C6: 52 | D6: 7 | E6: 7 | F6: 46208 | G6: =F6+D6 -> 46215 | H6: =G6+C6 -> 46267 | I6: =H6+E6 -> 46274
A7: SZ-01(623) | B7: SZ | C7: 52 | D7: 7 | E7: 7 | F7: 46218 | G7: =F7+D7 -> 46225 | H7: =G7+C7 -> 46277 | I7: =H7+E7 -> 46284
A8: SZ-02(623) | B8: SZ | C8: 52 | D8: 7 | E8: 7 | F8: 46244 | G8: =F8+D8 -> 46251 | H8: =G8+C8 -> 46303 | I8: =H8+E8 -> 46310
A9: IMP OP 350-26 40HQ | B9: NB | C9: 45 | D9: 7 | E9: 7 | F9: 46203 | G9: =F9+D9 -> 46210 | H9: =G9+C9 -> 46255 | I9: =H9+E9 -> 46262
A10: NB-01 | B10: NB | C10: 45 | D10: 7 | E10: 7 | F10: 46223 | G10: =F10+D10 -> 46230 | H10: =G10+C10 -> 46275 | I10: =H10+E10 -> 46282
A11: Rest items | B11: SZ | C11: 52 | D11: 7 | E11: 7 | F11: 46248 | G11: =F11+D11 -> 46255 | H11: =G11+C11 -> 46307 | I11: =H11+E11 -> 46314
